Workbook

Sheet Entries
A1: Show name | B1: Owner Id | C1: Owner title | D1: Owner first name | E1: Owner last name | F1: Owner address 1 | G1: Owner address 2 | H1: Owner town | I1: Owner county | J1: Owner postcode | K1: Owner country | L1: Owner phone | M1: Owner email address | N1: Owner registered name | O1: Vehicle registration | P1: Registered name | Q1: Registered number | R1: Breed | S1: Sex | T1: Date of birth | U1: Merit points | V1: Entered classes | W1: Preferred judge | X1: Extras | Y1: Confirmed acceptance of declaration | Z1: Withdraw all entries if balloted out of Championship C | AA1: Show address in catalogue | AB1: Notes to organiser | AC1: Date of Entry | AD1: Import
A2: WEST SUFFOLK OBEDIENCE - Sat 30th and Sun 31st May 2026 | B2: 677 | C2: Miss | D2: Yvonne | E2: Abra | F2: Kiln Farm | G2: Lower Road, Cavendish | H2: Sudbury | I2: Suffolk | J2: CO107QU | K2: United Kingdom | L2: 07885581115 | M2: yvonne_abra@hotmail.com | N2: Yvonne Abra | P2: Austmans Sirius Blue (A Ex) | Q2: AW04518001 | R2: Australian Cattle Dog | S2: Bitch | T2: 43784 | U2: 0 | V2: 6 | Y2: Yes | Z2: No | AA2: No | AC2: WyD
A3: WEST SUFFOLK OBEDIENCE - Sat 30th and Sun 31st May 2026 | B3: 677 | C3: Miss | D3: Yvonne | E3: Abra | F3: Kiln Farm | G3: Lower Road, Cavendish | H3: Sudbury | I3: Suffolk | J3: CO107QU | K3: United Kingdom | L3: 07885581115 | M3: yvonne_abra@hotmail.com | N3: Yvonne Abra | P3: Austmans Sirius Blue (A Ex) | Q3: AW04518001 | R3: Australian Cattle Dog | S3: Bitch | T3: 43784 | U3: 0 | V3: 7 | W3: Julie Sheldrake | Y3: Yes | Z3: No | AA3: No | AC3: WyD
A4: WEST SUFFOLK OBEDIENCE - Sat 30th and Sun 31st May 2026 | B4: 677 | C4: Miss | D4: Yvonne | E4: Abra | F4: Kiln Farm | G4: Lower Road, Cavendish | H4: Sudbury | I4: Suffolk | J4: CO107QU | K4: United Kingdom | L4: 07885581115 | M4: yvonne_abra@hotmail.com | N4: Yvonne Abra | P4: Austmans Sirius Blue (A Ex) | Q4: AW04518001 | R4: Australian Cattle Dog | S4: Bitch | T4: 43784 | U4: 0 | V4: 12 | Y4: Yes | Z4: No | AA4: No | AC4: WyD
A5: WEST SUFFOLK OBEDIENCE - Sat 30th and Sun 31st May 2026 | B5: 677 | C5: Miss | D5: Yvonne | E5: Abra | F5: Kiln Farm | G5: Lower Road, Cavendish | H5: Sudbury | I5: Suffolk | J5: CO107QU | K5: United Kingdom | L5: 07885581115 | M5: yvonne_abra@hotmail.com | N5: Yvonne Abra | P5: Austmans Sirius Blue (A Ex) | Q5: AW04518001 | R5: Australian Cattle Dog | S5: Bitch | T5: 43784 | U5: 0 | V5: 13 | W5: Ruth Britton | Y5: Yes | Z5: No | AA5: No | AC5: WyD
A6: WEST SUFFOLK OBEDIENCE - Sat 30th and Sun 31st May 2026 | B6: 677 | C6: Miss | D6: Yvonne | E6: Abra | F6: Kiln Farm | G6: Lower Road, Cavendish | H6: Sudbury | I6: Suffolk | J6: CO107QU | K6: United Kingdom | L6: 07885581115 | M6: yvonne_abra@hotmail.com | N6: Yvonne Abra | P6: Austmans Sirius Blue (A Ex) | Q6: AW04518001 | R6: Australian Cattle Dog | S6: Bitch | T6: 43784 | U6: 0 | V6: 14 | W6: Sandra Barnes | Y6: Yes | Z6: No | AA6: No | AC6: WyD
A7: WEST SUFFOLK OBEDIENCE - Sat 30th and Sun 31st May 2026 | B7: 6318 | C7: Mrs | D7: Julie | E7: Ainsworth | F7: 21 Orchard Croft | H7: Lowestoft | I7: Suffolk | J7: NR33 9JL | K7: United Kingdom | L7: 07710593802 | M7: sheezalady86@aol.com | N7: Julie Ainsworth | P7: Fyndd Sodor for Soxettt | Q7: AY09135541 | R7: BC | S7: Bitch | T7: 44076 | U7: 0 | V7: 1 | W7: Bridgette Cameron | Y7: Yes | Z7: No | AA7: No | AC7: WyD
A8: WEST SUFFOLK OBEDIENCE - Sat 30th and Sun 31st May 2026 | B8: 6318 | C8: Mrs | D8: Julie | E8: Ainsworth | F8: 21 Orchard Croft | H8: Lowestoft | I8: Suffolk | J8: NR33 9JL | K8: United Kingdom | L8: 07710593802 | M8: sheezalady86@aol.com | N8: Julie Ainsworth | P8: Fyndd Sodor for Soxettt | Q8: AY09135541 | R8: BC | S8: Bitch | T8: 44076 | U8: 0 | V8: 2 | W8: Claire Williams | Y8: Yes | Z8: No | AA8: No | AC8: WyD
A9: WEST SUFFOLK OBEDIENCE - Sat 30th and Sun 31st May 2026 | B9: 6318 | C9: Mrs | D9: Julie | E9: Ainsworth | F9: 21 Orchard Croft | H9: Lowestoft | I9: Suffolk | J9: NR33 9JL | K9: United Kingdom | L9: 07710593802 | M9: sheezalady86@aol.com | N9: Julie Ainsworth | P9: Mischief a D'Lite at Soxette | Q9: K0274232 | R9: WS | S9: Dog | T9: 45277 | U9: 0 | V9: 1 | W9: Bridgette Cameron | Y9: Yes | Z9: No | AA9: No | AC9: WyD
A10: WEST SUFFOLK OBEDIENCE - Sat 30th and Sun 31st May 2026 | B10: 6318 | C10: Mrs | D10: Julie | E10: Ainsworth | F10: 21 Orchard Croft | H10: Lowestoft | I10: Suffolk | J10: NR33 9JL | K10: United Kingdom | L10: 07710593802 | M10: sheezalady86@aol.com | N10: Julie Ainsworth | P10: Mischief a D'Lite at Soxette | Q10: K0274232 | R10: WS | S10: Dog | T10: 45277 | U10: 0 | V10: 2 | W10: Claire Williams | Y10: Yes | Z10: No | AA10: No | AC10: WyD
A11: WEST SUFFOLK OBEDIENCE - Sat 30th and Sun 31st May 2026 | B11: 6318 | C11: Mrs | D11: Julie | E11: Ainsworth | F11: 21 Orchard Croft | H11: Lowestoft | I11: Suffolk | J11: NR33 9JL | K11: United Kingdom | L11: 07710593802 | M11: sheezalady86@aol.com | N11: Julie Ainsworth | P11: Mischief a D'Lite at Soxette | Q11: K0274232 | R11: WS | S11: Dog | T11: 45277 | U11: 0 | V11: 3 | W11: Janet Stewart Baldry | Y11: Yes | Z11: No | AA11: No | AC11: WyD
A12: WEST SUFFOLK OBEDIENCE - Sat 30th and Sun 31st May 2026 | B12: 5307 | C12: Mrs | D12: Una | E12: Alexander | F12: Fairways Middle Green | G12: Wakes Colne | H12: Colechester | I12: Essex | J12: CO6 2BN | K12: United Kingdom | L12: 07954440355 | M12: una.a81@gmail.com | N12: Mrs UP & Mr MJ Alexander | P12: Chestnut Victor | Q12: K0267280 | R12: Cockapoo | S12: Dog | T12: 44147 | U12: 0 | V12: 1 | W12: Bridgette Cameron | Y12: Yes | Z12: No | AA12: No | AC12: WyD
A13: WEST SUFFOLK OBEDIENCE - Sat 30th and Sun 31st May 2026 | B13: 5307 | C13: Mrs | D13: Una | E13: Alexander | F13: Fairways Middle Green | G13: Wakes Colne | H13: Colechester | I13: Essex | J13: CO6 2BN | K13: United Kingdom | L13: 07954440355 | M13: una.a81@gmail.com | N13: Mrs UP & Mr MJ Alexander | P13: Chestnut Victor | Q13: K0267280 | R13: Cockapoo | S13: Dog | T13: 44147 | U13: 0 | V13: 2 | W13: Claire Williams | Y13: Yes | Z13: No | AA13: No | AC13: WyD
A14: WEST SUFFOLK OBEDIENCE - Sat 30th and Sun 31st May 2026 | B14: 3874 | C14: Mrs | D14: Angie | E14: Allen | F14: 10 Ashfield Crescent | H14: Lowestoft | I14: Suffolk | J14: NR33 9BE | K14: United Kingdom | L14: 07717774722 | M14: angela-allen1@sky.com | N14: Mrs A Allen | P14: Qimugta Malfy | Q14: BA18318101 | R14: Canadian Eskimo Fog | S14: Dog | T14: 44927 | U14: 0 | V14: 1 | W14: Bridgette Cameron | Y14: Yes | Z14: No | AA14: No | AC14: WyD
A15: WEST SUFFOLK OBEDIENCE - Sat 30th and Sun 31st May 2026 | B15: 3874 | C15: Mrs | D15: Angie | E15: Allen | F15: 10 Ashfield Crescent | H15: Lowestoft | I15: Suffolk | J15: NR33 9BE | K15: United Kingdom | L15: 07717774722 | M15: angela-allen1@sky.com | N15: Mrs A Allen | P15: Qimugta Malfy | Q15: BA18318101 | R15: Canadian Eskimo Fog | S15: Dog | T15: 44927 | U15: 0 | V15: 8 | W15: Alex Berry | Y15: Yes | Z15: No | AA15: No | AC15: WyD
A16: WEST SUFFOLK OBEDIENCE - Sat 30th and Sun 31st May 2026 | B16: 3874 | C16: Mrs | D16: Angie | E16: Allen | F16: 10 Ashfield Crescent | H16: Lowestoft | I16: Suffolk | J16: NR33 9BE | K16: United Kingdom | L16: 07717774722 | M16: angela-allen1@sky.com | N16: Mrs A Allen | P16: Qimugta Malfy | Q16: BA18318101 | R16: Canadian Eskimo Fog | S16: Dog | T16: 44927 | U16: 0 | V16: 2 | W16: Claire Williams | Y16: Yes | Z16: No | AA16: No | AC16: WyD
A17: WEST SUFFOLK OBEDIENCE - Sat 30th and Sun 31st May 2026 | B17: 701 | C17: Mrs | D17: Tracy | E17: Ansell | F17: 9 Bates close | H17: HIGHAM FERRES | I17: NORTHANTS | J17: NN10 8HF | K17: United Kingdom | L17: 01933353038 | M17: srallebone9@gmail.com | N17: Mrs Tracy Ansell | P17: Buskru Go With the Flo | Q17: K0269947 | R17: XB | S17: Bitch | T17: 44890 | U17: 0 | V17: 5 | W17: Gina Zantboer | X17: 1. Camping Friday Night (from Friday mid-day),2. Camping Sat Night | Y17: Yes | Z17: No | AA17: No | AC17: WyD
A18: WEST SUFFOLK OBEDIENCE - Sat 30th and Sun 31st May 2026 | B18: 701 | C18: Mrs | D18: Tracy | E18: Ansell | F18: 9 Bates close | H18: HIGHAM FERRES | I18: NORTHANTS | J18: NN10 8HF | K18: United Kingdom | L18: 01933353038 | M18: srallebone9@gmail.com | N18: Mrs Tracy Ansell | P18: Tazziemin Strike a Pose for Chalkwell | Q18: AZ15444205 | R18: Std Poodle | S18: Bitch | T18: 44754 | U18: 0 | V18: 5 | W18: Christine Richardson | X18: 1. Camping Friday Night (from Friday mid-day),2. Camping Sat Night | Y18: Yes | Z18: No | AA18: No | AC18: WyD
A19: WEST SUFFOLK OBEDIENCE - Sat 30th and Sun 31st May 2026 | B19: 701 | C19: Mrs | D19: Tracy | E19: Ansell | F19: 9 Bates close | H19: HIGHAM FERRES | I19: NORTHANTS | J19: NN10 8HF | K19: United Kingdom | L19: 01933353038 | M19: srallebone9@gmail.com | N19: Mrs Tracy Ansell | P19: Tazziemin Strike a Pose for Chalkwell | Q19: AZ15444205 | R19: Std Poodle | S19: Bitch | T19: 44754 | U19: 0 | V19: 6 | X19: 1. Camping Friday Night (from Friday mid-day),2. Camping Sat Night | Y19: Yes | Z19: No | AA19: No | AC19: WyD
A20: WEST SUFFOLK OBEDIENCE - Sat 30th and Sun 31st May 2026 | B20: 701 | C20: Mrs | D20: Tracy | E20: Ansell | F20: 9 Bates close | H20: HIGHAM FERRES | I20: NORTHANTS | J20: NN10 8HF | K20: United Kingdom | L20: 01933353038 | M20: srallebone9@gmail.com | N20: Mrs Tracy Ansell | P20: Chalkwell Worth a Shot | Q20: AU00900601 | R20: Std Poodle | S20: Dog | T20: 42657 | U20: 0 | V20: 7 | W20: Julie Sheldrake | X20: 1. Camping Friday Night (from Friday mid-day),2. Camping Sat Night | Y20: Yes | Z20: No | AA20: No | AC20: WyD
A21: WEST SUFFOLK OBEDIENCE - Sat 30th and Sun 31st May 2026 | B21: 701 | C21: Mrs | D21: Tracy | E21: Ansell | F21: 9 Bates close | H21: HIGHAM FERRES | I21: NORTHANTS | J21: NN10 8HF | K21: United Kingdom | L21: 01933353038 | M21: srallebone9@gmail.com | N21: Mrs Tracy Ansell | P21: Buskru Go With the Flo | Q21: K0269947 | R21: XB | S21: Bitch | T21: 44890 | U21: 0 | V21: 11 | W21: Sue Parmiter | X21: 1. Camping Friday Night (from Friday mid-day),2. Camping Sat Night | Y21: Yes | Z21: No | AA21: No | AC21: WyD
A22: WEST SUFFOLK OBEDIENCE - Sat 30th and Sun 31st May 2026 | B22: 701 | C22: Mrs | D22: Tracy | E22: Ansell | F22: 9 Bates close | H22: HIGHAM FERRES | I22: NORTHANTS | J22: NN10 8HF | K22: United Kingdom | L22: 01933353038 | M22: srallebone9@gmail.com | N22: Mrs Tracy Ansell | P22: Tazziemin Strike a Pose for Chalkwell | Q22: AZ15444205 | R22: Std Poodle | S22: Bitch | T22: 44754 | U22: 0 | V22: 11 | W22: Claire Jameson | X22: 1. Camping Friday Night (from Friday mid-day),2. Camping Sat Night | Y22: Yes | Z22: No | AA22: No | AC22: WyD
A23: WEST SUFFOLK OBEDIENCE - Sat 30th and Sun 31st May 2026 | B23: 701 | C23: Mrs | D23: Tracy | E23: Ansell | F23: 9 Bates close | H23: HIGHAM FERRES | I23: NORTHANTS | J23: NN10 8HF | K23: United Kingdom | L23: 01933353038 | M23: srallebone9@gmail.com | N23: Mrs Tracy Ansell | P23: Chalkwell Worth a Shot | Q23: AU00900601 | R23: Std Poodle | S23: Dog | T23: 42657 | U23: 0 | V23: 13 | W23: Ruth Britton | X23: 1. Camping Friday Night (from Friday mid-day),2. Camping Sat Night | Y23: Yes | Z23: No | AA23: No | AC23: WyD
A24: WEST SUFFOLK OBEDIENCE - Sat 30th and Sun 31st May 2026 | B24: 877 | C24: Mrs | D24: Julie | E24: Appleton | F24: 10 Belchamps Way | H24: Hockley | I24: Essex | J24: SS5 4NT | K24: United Kingdom | L24: 01702 201346 | M24: appleton.julie@btinternet.com | N24: Mrs Julie Appleton | P24: Purbarn Its Riders on a Storm at Applebel | Q24: BB24610206 | R24: Golden Retriever | S24: Bitch | T24: 45355 | U24: 0 | V24: 4 | W24: Christine Bowles | Y24: Yes | Z24: No | AA24: No | AC24: WyD
A25: WEST SUFFOLK OBEDIENCE - Sat 30th and Sun 31st May 2026 | B25: 877 | C25: Mrs | D25: Julie | E25: Appleton | F25: 10 Belchamps Way | H25: Hockley | I25: Essex | J25: SS5 4NT | K25: United Kingdom | L25: 01702 201346 | M25: appleton.julie@btinternet.com | N25: Mrs Julie Appleton | P25: Applebel Tamarind | Q25: AT04075001 | R25: Golden Retriever | S25: Bitch | T25: 42659 | U25: 0 | V25: 7 | W25: Julie Sheldrake | Y25: Yes | Z25: No | AA25: No | AC25: WyD
A26: WEST SUFFOLK OBEDIENCE - Sat 30th and Sun 31st May 2026 | B26: 877 | C26: Mrs | D26: Julie | E26: Appleton | F26: 10 Belchamps Way | H26: Hockley | I26: Essex | J26: SS5 4NT | K26: United Kingdom | L26: 01702 201346 | M26: appleton.julie@btinternet.com | N26: Mrs Julie Appleton | P26: Purbarn Its Riders on a Storm at Applebel | Q26: BB24610206 | R26: Golden Retriever | S26: Bitch | T26: 45355 | U26: 0 | V26: 10 | W26: No preference | Y26: Yes | Z26: No | AA26: No | AC26: WyD
A27: WEST SUFFOLK OBEDIENCE - Sat 30th and Sun 31st May 2026 | B27: 877 | C27: Mrs | D27: Julie | E27: Appleton | F27: 10 Belchamps Way | H27: Hockley | I27: Essex | J27: SS5 4NT | K27: United Kingdom | L27: 01702 201346 | M27: appleton.julie@btinternet.com | N27: Mrs Julie Appleton | P27: Applebel Tamarind | Q27: AT04075001 | R27: Golden Retriever | S27: Bitch | T27: 42659 | U27: 0 | V27: 13 | W27: Ruth Britton | Y27: Yes | Z27: No | AA27: No | AC27: WyD
A28: WEST SUFFOLK OBEDIENCE - Sat 30th and Sun 31st May 2026 | B28: 878 | C28: Mr | D28: Ian | E28: Appleton | F28: 10 Belchamps Way | H28: Hockley | I28: Essex | J28: SS5 4NT | K28: United Kingdom | L28: 01702 201346 | M28: appleton.ian@btinternet.com | N28: Mr Ian Appleton | P28: Applebel Tomatin | Q28: AY05276601 | R28: Golden Retriever | S28: Dog | T28: 44086 | U28: 0 | V28: 5 | W28: Gina Zantboer | Y28: Yes | Z28: No | AA28: No | AC28: WyD
A29: WEST SUFFOLK OBEDIENCE - Sat 30th and Sun 31st May 2026 | B29: 878 | C29: Mr | D29: Ian | E29: Appleton | F29: 10 Belchamps Way | H29: Hockley | I29: Essex | J29: SS5 4NT | K29: United Kingdom | L29: 01702 201346 | M29: appleton.ian@btinternet.com | N29: Mr Ian Appleton | P29: Applebel Tomatin | Q29: AY05276601 | R29: Golden Retriever | S29: Dog | T29: 44086 | U29: 0 | V29: 6 | Y29: Yes | Z29: No | AA29: No | AC29: WyD
A30: WEST SUFFOLK OBEDIENCE - Sat 30th and Sun 31st May 2026 | B30: 878 | C30: Mr | D30: Ian | E30: Appleton | F30: 10 Belchamps Way | H30: Hockley | I30: Essex | J30: SS5 4NT | K30: United Kingdom | L30: 01702 201346 | M30: appleton.ian@btinternet.com | N30: Mr Ian Appleton | P30: Applebel Tomatin | Q30: AY05276601 | R30: Golden Retriever | S30: Dog | T30: 44086 | U30: 0 | V30: 11 | W30: Claire Jameson | Y30: Yes | Z30: No | AA30: No | AC30: WyD
A31: WEST SUFFOLK OBEDIENCE - Sat 30th and Sun 31st May 2026 | B31: 878 | C31: Mr | D31: Ian | E31: Appleton | F31: 10 Belchamps Way | H31: Hockley | I31: Essex | J31: SS5 4NT | K31: United Kingdom | L31: 01702 201346 | M31: appleton.ian@btinternet.com | N31: Mr Ian Appleton | P31: Applebel Tomatin | Q31: AY05276601 | R31: Golden Retriever | S31: Dog | T31: 44086 | U31: 0 | V31: 12 | Y31: Yes | Z31: No | AA31: No | AC31: WyD
A32: WEST SUFFOLK OBEDIENCE - Sat 30th and Sun 31st May 2026 | B32: 6812 | C32: Mrs | D32: Angela | E32: Armstrong | F32: 10 Holt Farm Way | H32: Rochford | I32: Essex | J32: SS4 1SA | K32: United Kingdom | L32: 07779236870 | M32: angie.armstrong1954@gmail.com | N32: Mrs V & Mr K Walker | P32: Black Melanite (AY1) | Q32: AY06397805 | R32: Spaniel (Cocker) | S32: Bitch | T32: 44270 | U32: 0 | V32: 1 | W32: Bridgette Cameron | Y32: Yes | Z32: No | AA32: No | AC32: WyD
A33: WEST SUFFOLK OBEDIENCE - Sat 30th and Sun 31st May 2026 | B33: 6812 | C33: Mrs | D33: Angela | E33: Armstrong | F33: 10 Holt Farm Way | H33: Rochford | I33: Essex | J33: SS4 1SA | K33: United Kingdom | L33: 07779236870 | M33: angie.armstrong1954@gmail.com | N33: Mrs V & Mr K Walker | P33: Black Melanite (AY1) | Q33: AY06397805 | R33: Spaniel (Cocker) | S33: Bitch | T33: 44270 | U33: 0 | V33: 2 | W33: Claire Williams | Y33: Yes | Z33: No | AA33: No | AC33: WyD
A34: WEST SUFFOLK OBEDIENCE - Sat 30th and Sun 31st May 2026 | B34: 2342 | C34: Miss | D34: Katrina | E34: Arnold | F34: 17 Eden Way | H34: Warlingham | I34: Surrey | J34: CR6 9DP | K34: United Kingdom | L34: 07778388879 | M34: katrina.arnold@btinternet.com | N34: Miss K Arnold | P34: Tilemash Just In Time | Q34: KO275197 | R34: WS | S34: Dog | T34: 45348 | U34: 0 | V34: 4 | W34: No preference | Y34: Yes | Z34: No | AA34: No | AC34: WyD
A35: WEST SUFFOLK OBEDIENCE - Sat 30th and Sun 31st May 2026 | B35: 2342 | C35: Miss | D35: Katrina | E35: Arnold | F35: 17 Eden Way | H35: Warlingham | I35: Surrey | J35: CR6 9DP | K35: United Kingdom | L35: 07778388879 | M35: katrina.arnold@btinternet.com | N35: Miss K Arnold | P35: DeeAnn Reckless Eric | Q35: AV03405102 | R35: BC | S35: Dog | T35: 43302 | U35: 0 | V35: 6 | Y35: Yes | Z35: No | AA35: No | AC35: WyD
A36: WEST SUFFOLK OBEDIENCE - Sat 30th and Sun 31st May 2026 | B36: 2342 | C36: Miss | D36: Katrina | E36: Arnold | F36: 17 Eden Way | H36: Warlingham | I36: Surrey | J36: CR6 9DP | K36: United Kingdom | L36: 07778388879 | M36: katrina.arnold@btinternet.com | N36: Miss K Arnold | P36: DeeAnn Reckless Eric | Q36: AV03405102 | R36: BC | S36: Dog | T36: 43302 | U36: 0 | V36: 7 | W36: Julie Sheldrake | Y36: Yes | Z36: No | AA36: No | AC36: WyD
A37: WEST SUFFOLK OBEDIENCE - Sat 30th and Sun 31st May 2026 | B37: 6787 | C37: Mrs | D37: Isobel | E37: Ashbey | F37: 3 Pound Farm Barns | G37: Weston Colville | H37: CAMBRIDGE | I37: Cambridgeshire | J37: CB21 5NZ | K37: United Kingdom | L37: 07889686588 | M37: isobelashbey@gmail.com | N37: Isobel Ashbey | P37: Miles Buddlington | Q37: K0280619 | S37: Dog | T37: 44313 | U37: 0 | V37: 8 | W37: Alex Berry | Y37: Yes | Z37: No | AA37: No | AC37: WyD
A38: WEST SUFFOLK OBEDIENCE - Sat 30th and Sun 31st May 2026 | B38: 6787 | C38: Mrs | D38: Isobel | E38: Ashbey | F38: 3 Pound Farm Barns | G38: Weston Colville | H38: CAMBRIDGE | I38: Cambridgeshire | J38: CB21 5NZ | K38: United Kingdom | L38: 07889686588 | M38: isobelashbey@gmail.com | N38: Isobel Ashbey | P38: Miles Buddlington | Q38: K0280619 | S38: Dog | T38: 44313 | U38: 0 | V38: 9 | W38: Pam Durham | Y38: Yes | Z38: No | AA38: No | AC38: WyD
A39: WEST SUFFOLK OBEDIENCE - Sat 30th and Sun 31st May 2026 | B39: 6787 | C39: Mrs | D39: Isobel | E39: Ashbey | F39: 3 Pound Farm Barns | G39: Weston Colville | H39: CAMBRIDGE | I39: Cambridgeshire | J39: CB21 5NZ | K39: United Kingdom | L39: 07889686588 | M39: isobelashbey@gmail.com | N39: Isobel Ashbey | P39: Miles Buddlington | Q39: K0280619 | S39: Dog | T39: 44313 | U39: 0 | V39: 14 | W39: Sandra Barnes | Y39: Yes | Z39: No | AA39: No | AC39: WyD
A40: WEST SUFFOLK OBEDIENCE - Sat 30th and Sun 31st May 2026 | B40: 5751 | C40: Mrs | D40: Carol | E40: Ashby | F40: 12 RAYNHAM VILLAS, HUNTON ROAD, | H40: MARDEN, TONBRIDGE | I40: kent | J40: TN129SZ | K40: United Kingdom | L40: 01622 820791 | M40: invicta2@hotmail.co.uk | N40: Carol Ashby | P40: Lovely Dovelee | Q40: k0270418 | R40: jackapoo | S40: Bitch | T40: 44827 | U40: 0 | V40: 4 | W40: No preference | Y40: Yes | Z40: No | AA40: No | AC40: WyD
...

Sheet Checks
A1: Class Number | B1: Class Name | C1: Total Entries | D1: Number in Part 1 | E1: Number in Part 2 | F1: Judge | G1: Judge Part 2 | I1: WYD | J1: Paper | K1: Totals
A2: 1 | B2: INTRODUCTORY (DOG & BITCH) | C2: =COUNTIF(Entries!$V$1:$V$744,$A2) -> 19 | F2: Bridgette Cameron | I2: 19 | J2: 0 | K2: =I2+J2 -> 19
A3: 2 | B3: PRE-BEGINNER (DOG & BITCH) | C3: =COUNTIF(Entries!$V$1:$V$744,$A3) -> 25 | F3: Claire Williams | I3: 24 | J3: 1 | K3: =I3+J3 -> 25
A4: 3 | B4: BEGINNER (DOG & BITCH) | C4: =COUNTIF(Entries!$V$1:$V$744,$A4) -> 27 | F4: Janet Stewart Baldry | I4: 25 | J4: 2 | K4: =I4+J4 -> 27
A5: 4 | B5: NOVICE (DOG & BITCH) | C5: =COUNTIF(Entries!$V$1:$V$744,$A5) -> 92 | D5: =ROUND(C5/2,) -> 46 | E5: =C5-D5 -> 46 | F5: Christine Bowles | G5: Suzanne Walker | I5: 84 | J5: 8 | K5: =I5+J5 -> 92
A6: 5 | B6: CLASS 'A' (DOG & BITCH) | C6: =COUNTIF(Entries!$V$1:$V$744,$A6) -> 80 | D6: =ROUND(C6/2,) -> 40 | E6: =C6-D6 -> 40 | F6: Gina Zantboer | G6: Christine Richardson | I6: 71 | J6: 9 | K6: =I6+J6 -> 80
A7: 6 | B7: CLASS 'B' (DOG & BITCH) | C7: =COUNTIF(Entries!$V$1:$V$744,$A7) -> 72 | D7: =ROUND(C7/2,) -> 36 | E7: =C7-D7 -> 36 | F7: Georgie Riches | G7: Kath Westell | I7: 65 | J7: 7 | K7: =I7+J7 -> 72
A8: 7 | B8: CLASS 'C' (DOG & BITCH) | C8: =COUNTIF(Entries!$V$1:$V$744,$A8) -> 49 | F8: Julie Sheldrake | I8: 45 | J8: 4 | K8: =I8+J8 -> 49
A9: 8 | B9: PRE-BEGINNER (DOG & BITCH) | C9: =COUNTIF(Entries!$V$1:$V$744,$A9) -> 31 | F9: Alex Berry | I9: 31 | J9: 0 | K9: =I9+J9 -> 31
A10: 9 | B10: BEGINNER (DOG & BITCH) | C10: =COUNTIF(Entries!$V$1:$V$744,$A10) -> 33 | F10: Pam Durham | I10: 32 | J10: 1 | K10: =I10+J10 -> 33
A11: 10 | B11: NOVICE (DOG & BITCH) | C11: =COUNTIF(Entries!$V$1:$V$744,$A11) -> 85 | D11: =ROUND(C11/2,) -> 43 | E11: =C11-D11 -> 42 | F11: Miranda Humphries | G11: Tina Keene | I11: 78 | J11: 7 | K11: =I11+J11 -> 85
A12: 11 | B12: CLASS 'A' (DOG & BITCH) | C12: =COUNTIF(Entries!$V$1:$V$744,$A12) -> 77 | D12: =ROUND(C12/2,) -> 39 | E12: =C12-D12 -> 38 | F12: Claire Jameson | G12: Sue Parmiter | I12: 68 | J12: 9 | K12: =I12+J12 -> 77
A13: 12 | B13: CLASS 'B' (DOG & BITCH) | C13: =COUNTIF(Entries!$V$1:$V$744,$A13) -> 71 | D13: =ROUND(C13/2,) -> 36 | E13: =C13-D13 -> 35 | F13: Victoria Cook | G13: Jude Stone | I13: 64 | J13: 7 | K13: =I13+J13 -> 71
A14: 13 | B14: CLASS 'C' (DOG & BITCH) | C14: =COUNTIF(Entries!$V$1:$V$744,$A14) -> 53 | F14: Ruth Britton | I14: 48 | J14: 5 | K14: =I14+J14 -> 53
A15: 14 | B15: SPECIAL FUN CLASS | C15: =COUNTIF(Entries!$V$1:$V$744,$A15) -> 29 | F15: Sandra Barnes | I15: 29 | J15: 0 | K15: =I15+J15 -> 29
C17: =SUM(C1:C15) -> 743
C19: =C17*7 -> 5201

Sheet Camping
A1: Name | B1: Email | C1: Phone | D1: Fri | E1: Sat | F1: Sun | G1: Notes
A2: Miss Gill Garraway | B2: gill.underwood1978@gmail.com | C2: 07805190544 | D2: Y | E2: Y
A3: Miss Jennifer Marriott | B3: ifermarriott@yahoo.co.uk | C3: 07798894991 | D3: Y | E3: Y
A4: Miss Jessica Lewis | B4: jess.l@sky.com | C4: 02475017046 | D4: Y | E4: Y
A5: Miss Kathy Woodgreaves | B5: k.woodgreaves666@btinternet.com | C5: 07745415909 | E5: Y
A6: Miss Kim Mercer | B6: kim.walkies@btinternet.com | D6: Y | E6: Y | F6: Y
A7: Miss Miranda Humphreys | B7: miranda.3labs@gmail.com | C7: 447587132666 | D7: Y | E7: Y
A8: Miss Rosie Colwood | B8: r.c.colwood@gmail.com | C8: 01924897723 | D8: Y | E8: Y | F8: Y
A9: Miss Victoria Main | B9: vmain72@googlemail.com | C9: 07988 604447 | D9: Y | E9: Y
A10: Mr Alex Berry | B10: alexjberry83@gmail.com | C10: 07514421698 | D10: Y | E10: Y | F10: Y
A11: Mr geoff painting | B11: geoff.painting@gmail.com | C11: 01932348810 | D11: Y | E11: Y | F11: Y
A12: Mr GRAHAM DYKE | B12: grahamdyke1@hotmail.co.uk | C12: 07736693937 | D12: Y | E12: Y
A13: Mr Sue Benstock | B13: lizajim@googlemail.com | C13: 07806 923568 | D13: Y | E13: Y | F13: Y
A14: Mrs A Mann | B14: k9ufd@yahoo.co.uk | C14: 01924272344 | D14: Y | E14: Y | G14: Could we camp near the rings please due to me being an amputee and on oxygen, thank you_x000D_ I'm not sure if you need my hubby Alistair as your first aider,
A15: Mrs angela whitnell | B15: angelawhitnell@yahoo.com | C15: 01787 223864 | D15: Y | E15: Y
A16: Mrs Carol Stewart | B16: carol@mojucabordercollies.com | C16: 01795 585401 | D16: Y | E16: Y
A17: Mrs Caroline Gebbie | B17: caroline@ukpet.com | C17: 07739714787 | D17: Y | E17: Y
A18: Mrs Christine Richardson | B18: crichardson@hotmail.co.uk | C18: 07775 728708 | D18: Y | E18: FREE | G18: Claiming Saturday night as judging
A19: Mrs Clair Dick | B19: clairhelen@googlemail.com | C19: 01394385872 | D19: Y | E19: Y | F19: Y
A20: Mrs Denise Platts | B20: deniseplatts1@icloud.com | C20: 07702740809 | D20: Y | E20: Y
A21: Mrs Geraldine Steadman | B21: geraldinesteadman@hotmail.com | C21: 07891477539 | E21: Y
A22: Mrs Helen Clarence | B22: helen.clarence@hotmail.co.uk | C22: 01777 710321 | D22: Y | E22: Y
A23: Mrs Helen Jermy | B23: c.jermy@tiscali.co.uk | C23: 01502733270 | D23: Y | E23: Y | F23: Y
A24: Mrs Jane Hall | B24: janehall114@gmail.com | C24: 07428 199564 | D24: Y | E24: Y
A25: Mrs Jennifer Runge | B25: jenny.runge@gmx.net | C25: 00491632497972 | D25: Y | E25: Y | F25: Y
A26: Mrs Julie Sheldrake | B26: vegrun@gmail.com | C26: 07975509533 | D26: Y | E26: Y
A27: Mrs Lesley Taylor | B27: taylormadeflowers@yahoo.co.uk | C27: 07970257329 | D27: Y | E27: Y
A28: Mrs LYNDA middlemas | B28: laurelbankfarm@yahoo.co.uk | C28: 01455209210 | D28: Y | E28: Y
A29: Mrs Lynda Snowling | B29: colinsnowling@btinternet.com | C29: 01502 731480 | D29: Y | E29: Y | F29: Y
A30: Mrs Lynne Darby | B30: lynnedarby@blueyonder.co.uk | C30: 01527 452562 | D30: Y | E30: Y | F30: Y
A31: Mrs Monika Dobbs | B31: monikadobbs@hotmail.co.uk | C31: 01525 643734 | D31: Y | E31: Y
A32: Mrs Patricia Gage | B32: snowtaggy@hotmail.com | C32: 01371873412 | D32: Y | E32: Y
A33: Mrs Rhonda Stokes | B33: rhonda.stokes@btinternet.com | C33: 07931706545 | D33: Y | E33: Y | F33: Y
A34: Mrs Sandra Samways | B34: samways237@btinternet.com | C34: 01945430651 | D34: Y | E34: Y
A35: Mrs Sonia Elvin | B35: soniaelvin19@gmail.com | C35: 01379644063 | D35: Y | E35: Y
A36: Mrs Sue Jaggers | B36: jim.jaggers@btinternet.com | C36: 01279812785 | D36: Y | E36: Y | F36: Y
A37: Mrs Susan Parmiter | B37: sgparmiter@icloud.com | C37: 01406478422 | D37: Y | E37: FREE | G37: Free camping night Sat plz .
A38: Mrs Tracy Ansell | B38: srallebone9@gmail.com | C38: 01933353038 | D38: Y | E38: Y
A39: Mrs Tracy Jackaman | B39: tracy.jackaman@outlook.com | C39: 07599183342 | E39: Y
A40: Mrs TRUDY HYMAN | B40: trudos1970@gmail.com | C40: 01924 830853 | D40: Y | E40: Y
...

Sheet NFC
A1: Show name | B1: Owner Id | C1: Owner title | D1: Owner first name | E1: Owner last name | F1: Owner address 1 | G1: Owner address 2 | H1: Owner town | I1: Owner county | J1: Owner postcode | K1: Owner country | L1: Owner phone | M1: Owner email address | N1: Owner registered name | O1: Vehicle registration | P1: Registered name | Q1: Registered number | R1: Breed | S1: Sex | T1: Date of birth | U1: Merit points | V1: Entered classes | W1: Preferred judge | X1: Extras | Y1: Confirmed acceptance of declaration | Z1: Withdraw all entries if balloted out of Championship C | AA1: Show address in catalogue | AB1: Notes to organiser
A2: WEST SUFFOLK OBEDIENCE - Sat 30th and Sun 31st May 2026 | B2: 677 | C2: Miss | D2: Yvonne | E2: Abra | F2: Kiln Farm | G2: Lower Road, Cavendish | H2: Sudbury | I2: Suffolk | J2: CO107QU | K2: United Kingdom | L2: 07885581115 | M2: yvonne_abra@hotmail.com | N2: Yvonne Abra | P2: Austmans Goody two Shoes | Q2: BA21468502 | R2: Australian Cattle Dog | S2: Bitch | T2: 45151 | U2: 0 | V2: 0 | W2: Not applicable | Y2: Yes | Z2: No | AA2: No
A3: WEST SUFFOLK OBEDIENCE - Sat 30th and Sun 31st May 2026 | B3: 677 | C3: Miss | D3: Yvonne | E3: Abra | F3: Kiln Farm | G3: Lower Road, Cavendish | H3: Sudbury | I3: Suffolk | J3: CO107QU | K3: United Kingdom | L3: 07885581115 | M3: yvonne_abra@hotmail.com | N3: Yvonne Abra | P3: Austmans Goody two Shoes | Q3: BA21468502 | R3: Australian Cattle Dog | S3: Bitch | T3: 45151 | U3: 0 | V3: 0 | W3: Not applicable | Y3: Yes | Z3: No | AA3: No
A4: WEST SUFFOLK OBEDIENCE - Sat 30th and Sun 31st May 2026 | B4: 878 | C4: Mr | D4: Ian | E4: Appleton | F4: 10 Belchamps Way | H4: Hockley | I4: Essex | J4: SS5 4NT | K4: United Kingdom | L4: 01702 201346 | M4: appleton.ian@btinternet.com | N4: Mr Ian Appleton | P4: Applebel Merlot | Q4: AS00342901 | R4: Golden Retriever | S4: Dog | T4: 42013 | U4: 0 | V4: 0 | W4: Not applicable | Y4: Yes | Z4: No | AA4: No
A5: WEST SUFFOLK OBEDIENCE - Sat 30th and Sun 31st May 2026 | B5: 878 | C5: Mr | D5: Ian | E5: Appleton | F5: 10 Belchamps Way | H5: Hockley | I5: Essex | J5: SS5 4NT | K5: United Kingdom | L5: 01702 201346 | M5: appleton.ian@btinternet.com | N5: Mr Ian Appleton | P5: Applebel Merlot | Q5: AS00342901 | R5: Golden Retriever | S5: Dog | T5: 42013 | U5: 0 | V5: 0 | W5: Not applicable | Y5: Yes | Z5: No | AA5: No
A6: WEST SUFFOLK OBEDIENCE - Sat 30th and Sun 31st May 2026 | B6: 2342 | C6: Miss | D6: Katrina | E6: Arnold | F6: 17 Eden Way | H6: Warlingham | I6: Surrey | J6: CR6 9DP | K6: United Kingdom | L6: 07778388879 | M6: katrina.arnold@btinternet.com | N6: Miss K Arnold | P6: DeeAnn Reckless Eric | Q6: AV03405102 | R6: Border Collie | S6: Dog | T6: 43302 | U6: 0 | V6: 0 | W6: Not applicable | Y6: Yes | Z6: No | AA6: No
A7: WEST SUFFOLK OBEDIENCE - Sat 30th and Sun 31st May 2026 | B7: 2342 | C7: Miss | D7: Katrina | E7: Arnold | F7: 17 Eden Way | H7: Warlingham | I7: Surrey | J7: CR6 9DP | K7: United Kingdom | L7: 07778388879 | M7: katrina.arnold@btinternet.com | N7: Miss K Arnold | P7: Tilemash Just In Time | Q7: KO275197 | R7: Working Sheepdog | S7: Dog | T7: 45348 | U7: 0 | V7: 0 | W7: Not applicable | Y7: Yes | Z7: No | AA7: No
A8: WEST SUFFOLK OBEDIENCE - Sat 30th and Sun 31st May 2026 | B8: 5751 | C8: Mrs | D8: CAROL | E8: ASHBY | F8: 12 RAYNHAM VILLAS, HUNTON ROAD, | H8: MARDEN, TONBRIDGE | I8: kent | J8: TN129SZ | K8: United Kingdom | L8: 01622 820791 | M8: invicta2@hotmail.co.uk | N8: Carol Ashby | P8: Luna lux | Q8: k0266318 | R8: german shepherd | S8: Bitch | T8: 44034 | U8: 0 | V8: 0 | W8: Not applicable | Y8: Yes | Z8: No | AA8: No
A9: WEST SUFFOLK OBEDIENCE - Sat 30th and Sun 31st May 2026 | B9: 683 | C9: Miss | D9: Debbie | E9: Back | F9: 68 Albert Street | H9: Spalding | I9: Lincs | J9: PE11 2LD | K9: United Kingdom | L9: 07979962230 | M9: debzdoggz@gmail.com | N9: Miss Debbie Back | P9: DEBAKS NOTAFF AHKENKOLLI | Q9: K149598 | R9: CROSSBREED | S9: Dog | T9: 41847 | U9: 0 | V9: 0 | W9: Not applicable | Y9: Yes | Z9: No | AA9: No
A10: WEST SUFFOLK OBEDIENCE - Sat 30th and Sun 31st May 2026 | B10: 683 | C10: Miss | D10: Debbie | E10: Back | F10: 68 Albert Street | H10: Spalding | I10: Lincs | J10: PE11 2LD | K10: United Kingdom | L10: 07979962230 | M10: debzdoggz@gmail.com | N10: Miss Debbie Back | P10: DEBAKS PHAYKIT TILYA MAYKIT | Q10: K0276438 | R10: LURCHER | S10: Dog | T10: 45501 | U10: 0 | V10: 0 | W10: Not applicable | Y10: Yes | Z10: No | AA10: No
A11: WEST SUFFOLK OBEDIENCE - Sat 30th and Sun 31st May 2026 | B11: 683 | C11: Miss | D11: Debbie | E11: Back | F11: 68 Albert Street | H11: Spalding | I11: Lincs | J11: PE11 2LD | K11: United Kingdom | L11: 07979962230 | M11: debzdoggz@gmail.com | N11: Miss Debbie Back | P11: LYNZENSU HOT TO TROT | Q11: AU04035701 | R11: STANDARD POODLE | S11: Dog | T11: 42992 | U11: 0 | V11: 0 | W11: Not applicable | Y11: Yes | Z11: No | AA11: No
A12: WEST SUFFOLK OBEDIENCE - Sat 30th and Sun 31st May 2026 | B12: 683 | C12: Miss | D12: Debbie | E12: Back | F12: 68 Albert Street | H12: Spalding | I12: Lincs | J12: PE11 2LD | K12: United Kingdom | L12: 07979962230 | M12: debzdoggz@gmail.com | N12: Miss Debbie Back | P12: TAYKTHA BAYTE | Q12: K162830 | R12: CROSSBREED | S12: Bitch | T12: 43291 | U12: 0 | V12: 0 | W12: Not applicable | Y12: Yes | Z12: No | AA12: No
A13: WEST SUFFOLK OBEDIENCE - Sat 30th and Sun 31st May 2026 | B13: 683 | C13: Miss | D13: Debbie | E13: Back | F13: 68 Albert Street | H13: Spalding | I13: Lincs | J13: PE11 2LD | K13: United Kingdom | L13: 07979962230 | M13: debzdoggz@gmail.com | N13: Miss Debbie Back | P13: DEBAKS NOTAFF AHKENKOLLI | Q13: K149598 | R13: CROSSBREED | S13: Dog | T13: 41847 | U13: 0 | V13: 0 | W13: Not applicable | Y13: Yes | Z13: No | AA13: No
A14: WEST SUFFOLK OBEDIENCE - Sat 30th and Sun 31st May 2026 | B14: 683 | C14: Miss | D14: Debbie | E14: Back | F14: 68 Albert Street | H14: Spalding | I14: Lincs | J14: PE11 2LD | K14: United Kingdom | L14: 07979962230 | M14: debzdoggz@gmail.com | N14: Miss Debbie Back | P14: DEBAKS PHAYKIT TILYA MAYKIT | Q14: K0276438 | R14: LURCHER | S14: Dog | T14: 45501 | U14: 0 | V14: 0 | W14: Not applicable | Y14: Yes | Z14: No | AA14: No
A15: WEST SUFFOLK OBEDIENCE - Sat 30th and Sun 31st May 2026 | B15: 683 | C15: Miss | D15: Debbie | E15: Back | F15: 68 Albert Street | H15: Spalding | I15: Lincs | J15: PE11 2LD | K15: United Kingdom | L15: 07979962230 | M15: debzdoggz@gmail.com | N15: Miss Debbie Back | P15: TAYKTHA BAYTE | Q15: K162830 | R15: CROSSBREED | S15: Bitch | T15: 43291 | U15: 0 | V15: 0 | W15: Not applicable | Y15: Yes | Z15: No | AA15: No
A16: WEST SUFFOLK OBEDIENCE - Sat 30th and Sun 31st May 2026 | B16: 1131 | C16: Ms | D16: Donna | E16: Bastin | F16: 9 William Court | G16: Aspley | H16: Hemel Hempstead | I16: Herts | J16: HP3 0AY | K16: United Kingdom | L16: 01442 405387 | M16: donna.bastin@ntlworld.com | N16: Donna Bastin | P16: Landini New Vision Nov Ex | Q16: K154303 | R16: Working Sheepdog | S16: Bitch | T16: 42451 | U16: 0 | V16: 0 | W16: Not applicable | Y16: Yes | Z16: No | AA16: No
A17: WEST SUFFOLK OBEDIENCE - Sat 30th and Sun 31st May 2026 | B17: 1131 | C17: Ms | D17: Donna | E17: Bastin | F17: 9 William Court | G17: Aspley | H17: Hemel Hempstead | I17: Herts | J17: HP3 0AY | K17: United Kingdom | L17: 01442 405387 | M17: donna.bastin@ntlworld.com | N17: Donna Bastin | P17: Landini New Vision Nov Ex | Q17: K154303 | R17: Working Sheepdog | S17: Bitch | T17: 42451 | U17: 0 | V17: 0 | W17: Not applicable | Y17: Yes | Z17: No | AA17: No
A18: WEST SUFFOLK OBEDIENCE - Sat 30th and Sun 31st May 2026 | B18: 54 | C18: Ms | D18: Rosemary | E18: Bate | F18: Corner Farm, Sibton | G18: Sibton | H18: Saxmundham | I18: Please select a region, state or province. | J18: IP17 2NE | K18: United Kingdom | L18: 441728660244 | M18: rosemary.bate@googlemail.com | N18: Rose Bate | P18: Chasing The Wind Around Robate | Q18: AZ12386103 | R18: English Springer Spaniel | S18: Bitch | T18: 44376 | U18: 0 | V18: 0 | W18: Not applicable | X18: 1. Camping Friday Night (from Friday mid-day),2. Camping Sat Night | Y18: Yes | Z18: No | AA18: No
A19: WEST SUFFOLK OBEDIENCE - Sat 30th and Sun 31st May 2026 | B19: 54 | C19: Ms | D19: Rosemary | E19: Bate | F19: Corner Farm, Sibton | G19: Sibton | H19: Saxmundham | I19: Please select a region, state or province. | J19: IP17 2NE | K19: United Kingdom | L19: 441728660244 | M19: rosemary.bate@googlemail.com | N19: Rose Bate | P19: Gipping Valley Flame Robate | Q19: BB0924942 | R19: Border Collie | S19: Bitch | T19: 45332 | U19: 0 | V19: 0 | W19: Not applicable | X19: 1. Camping Friday Night (from Friday mid-day),2. Camping Sat Night | Y19: Yes | Z19: No | AA19: No
A20: WEST SUFFOLK OBEDIENCE - Sat 30th and Sun 31st May 2026 | B20: 54 | C20: Ms | D20: Rosemary | E20: Bate | F20: Corner Farm, Sibton | G20: Sibton | H20: Saxmundham | I20: Please select a region, state or province. | J20: IP17 2NE | K20: United Kingdom | L20: 441728660244 | M20: rosemary.bate@googlemail.com | N20: Rose Bate | P20: Mago Barker Conquers Robate | Q20: K165544 | R20: Crossbreed | S20: Dog | T20: 43609 | U20: 0 | V20: 0 | W20: Not applicable | X20: 1. Camping Friday Night (from Friday mid-day),2. Camping Sat Night | Y20: Yes | Z20: No | AA20: No
A21: WEST SUFFOLK OBEDIENCE - Sat 30th and Sun 31st May 2026 | B21: 54 | C21: Ms | D21: Rosemary | E21: Bate | F21: Corner Farm, Sibton | G21: Sibton | H21: Saxmundham | I21: Please select a region, state or province. | J21: IP17 2NE | K21: United Kingdom | L21: 441728660244 | M21: rosemary.bate@googlemail.com | N21: Rose Bate | P21: Chasing The Wind Around Robate | Q21: AZ12386103 | R21: English Springer Spaniel | S21: Bitch | T21: 44376 | U21: 0 | V21: 0 | W21: Not applicable | X21: 1. Camping Friday Night (from Friday mid-day),2. Camping Sat Night | Y21: Yes | Z21: No | AA21: No
A22: WEST SUFFOLK OBEDIENCE - Sat 30th and Sun 31st May 2026 | B22: 54 | C22: Ms | D22: Rosemary | E22: Bate | F22: Corner Farm, Sibton | G22: Sibton | H22: Saxmundham | I22: Please select a region, state or province. | J22: IP17 2NE | K22: United Kingdom | L22: 441728660244 | M22: rosemary.bate@googlemail.com | N22: Rose Bate | P22: Gipping Valley Flame Robate | Q22: BB0924942 | R22: Border Collie | S22: Bitch | T22: 45332 | U22: 0 | V22: 0 | W22: Not applicable | X22: 1. Camping Friday Night (from Friday mid-day),2. Camping Sat Night | Y22: Yes | Z22: No | AA22: No
A23: WEST SUFFOLK OBEDIENCE - Sat 30th and Sun 31st May 2026 | B23: 54 | C23: Ms | D23: Rosemary | E23: Bate | F23: Corner Farm, Sibton | G23: Sibton | H23: Saxmundham | I23: Please select a region, state or province. | J23: IP17 2NE | K23: United Kingdom | L23: 441728660244 | M23: rosemary.bate@googlemail.com | N23: Rose Bate | P23: Mago Barker Conquers Robate | Q23: K165544 | R23: Crossbreed | S23: Dog | T23: 43609 | U23: 0 | V23: 0 | W23: Not applicable | X23: 1. Camping Friday Night (from Friday mid-day),2. Camping Sat Night | Y23: Yes | Z23: No | AA23: No
A24: WEST SUFFOLK OBEDIENCE - Sat 30th and Sun 31st May 2026 | B24: 4237 | C24: Mr | D24: Alex | E24: Berry | F24: 91 Church Street | H24: Great Harwood | I24: Lancashire | J24: BB6 7QB | K24: United Kingdom | L24: 07514421698 | M24: alexjberry83@gmail.com | N24: Mr Alexander J Berry | P24: Bat Ears | Q24: K166783 | R24: Chihuahua cross Miniature Pinscher | S24: Dog | T24: 43388 | U24: 0 | V24: 0 | W24: Not applicable | X24: 1. Camping Friday Night (from Friday mid-day),2. Camping Sat Night,3. Camping Sunday Night (must be gone by 11:00 am) | Y24: Yes | Z24: No | AA24: No
A25: WEST SUFFOLK OBEDIENCE - Sat 30th and Sun 31st May 2026 | B25: 4237 | C25: Mr | D25: Alex | E25: Berry | F25: 91 Church Street | H25: Great Harwood | I25: Lancashire | J25: BB6 7QB | K25: United Kingdom | L25: 07514421698 | M25: alexjberry83@gmail.com | N25: Mr Alexander J Berry | P25: Bat Ears | Q25: K166783 | R25: Chihuahua cross Miniature Pinscher | S25: Dog | T25: 43388 | U25: 0 | V25: 0 | W25: Not applicable | X25: 1. Camping Friday Night (from Friday mid-day),2. Camping Sat Night,3. Camping Sunday Night (must be gone by 11:00 am) | Y25: Yes | Z25: No | AA25: No
A26: WEST SUFFOLK OBEDIENCE - Sat 30th and Sun 31st May 2026 | B26: 4237 | C26: Mr | D26: Alex | E26: Berry | F26: 91 Church Street | H26: Great Harwood | I26: Lancashire | J26: BB6 7QB | K26: United Kingdom | L26: 07514421698 | M26: alexjberry83@gmail.com | N26: Mr Alexander J Berry | P26: Villensia Visage | Q26: BB23736706 | R26: English Bull Terrier | S26: Bitch | T26: 45292 | U26: 0 | V26: 0 | W26: Not applicable | X26: 1. Camping Friday Night (from Friday mid-day),2. Camping Sat Night,3. Camping Sunday Night (must be gone by 11:00 am) | Y26: Yes | Z26: No | AA26: No
A27: WEST SUFFOLK OBEDIENCE - Sat 30th and Sun 31st May 2026 | B27: 4237 | C27: Mr | D27: Alex | E27: Berry | F27: 91 Church Street | H27: Great Harwood | I27: Lancashire | J27: BB6 7QB | K27: United Kingdom | L27: 07514421698 | M27: alexjberry83@gmail.com | N27: Mr Alexander J Berry | P27: Villensia Visage | Q27: BB23736706 | R27: English Bull Terrier | S27: Bitch | T27: 45292 | U27: 0 | V27: 0 | W27: Not applicable | X27: 1. Camping Friday Night (from Friday mid-day),2. Camping Sat Night,3. Camping Sunday Night (must be gone by 11:00 am) | Y27: Yes | Z27: No | AA27: No
A28: WEST SUFFOLK OBEDIENCE - Sat 30th and Sun 31st May 2026 | B28: 1849 | C28: Mrs | D28: Christine | E28: Bowles | F28: 42 Oxfield Drive | G28: Gorefield | H28: Wisbech | I28: Cambridgeshire | J28: PE13 4LX | K28: United Kingdom | L28: 01945 870525 | M28: christinebowles21@googlemail.com | N28: Mrs C Bowles | P28: Hellene Wish Upon A Star | Q28: AY11384603 | R28: Border Collie | S28: Bitch | T28: 44477 | V28: 0 | W28: Not applicable | Y28: Yes | Z28: No | AA28: No | AB28: If required for a draw can it please be in C with Hellene Wish Upon A Star. Many thanks üòä
A29: WEST SUFFOLK OBEDIENCE - Sat 30th and Sun 31st May 2026 | B29: 1849 | C29: Mrs | D29: Christine | E29: Bowles | F29: 42 Oxfield Drive | G29: Gorefield | H29: Wisbech | I29: Cambridgeshire | J29: PE13 4LX | K29: United Kingdom | L29: 01945 870525 | M29: christinebowles21@googlemail.com | N29: Mrs C Bowles | P29: Maccadale Izzy | Q29: AT0000101 | R29: Border Collie | S29: Bitch | T29: 42215 | V29: 0 | W29: Not applicable | Y29: Yes | Z29: No | AA29: No | AB29: If required for a draw can it please be in C with Hellene Wish Upon A Star. Many thanks üòä
A30: WEST SUFFOLK OBEDIENCE - Sat 30th and Sun 31st May 2026 | B30: 660 | C30: Mrs | D30: Jane | E30: Bowman | F30: Colne View | G30: Brightlingsea Road | H30: Thorrington | I30: Essex | J30: CO7 8JJ | K30: United Kingdom | L30: 01206 302 309 | M30: tecwyn85@gmail.com | N30: Mrs Jane Bowman | P30: Tri again Katie | Q30: K153597 | R30: Working Sheepdog | S30: Bitch | T30: 42417 | U30: 0 | V30: 0 | W30: Not applicable | Y30: Yes | Z30: No | AA30: No | AB30: Happy to have a running order with Westoning Omen if convenient to you.
A31: WEST SUFFOLK OBEDIENCE - Sat 30th and Sun 31st May 2026 | B31: 660 | C31: Mrs | D31: Jane | E31: Bowman | F31: Colne View | G31: Brightlingsea Road | H31: Thorrington | I31: Essex | J31: CO7 8JJ | K31: United Kingdom | L31: 01206 302 309 | M31: tecwyn85@gmail.com | N31: Mrs Jane Bowman | P31: Tri again Katie | Q31: K153597 | R31: Working Sheepdog | S31: Bitch | T31: 42417 | U31: 0 | V31: 0 | W31: Not applicable | Y31: Yes | Z31: No | AA31: No | AB31: Happy to have a running order with Westoning Omen if convenient to you.
A32: WEST SUFFOLK OBEDIENCE - Sat 30th and Sun 31st May 2026 | B32: 1801 | C32: Ms | D32: Ruth | E32: Britton | F32: 14 Shrubwood Close | G32: Heckington | H32: Sleaford | I32: Lincolnshire | J32: NG34 9QH | K32: United Kingdom | L32: 01529461583 | M32: ruth.britton@btinternet.com | N32: Ruth Britton | P32: Summertime Remror Delight | Q32: K143791 | R32: Working Sheepdog | S32: Dog | T32: 41300 | U32: 0 | V32: 0 | W32: Not applicable | Y32: Yes | Z32: No | AA32: No
A33: WEST SUFFOLK OBEDIENCE - Sat 30th and Sun 31st May 2026 | B33: 1320 | C33: Mrs | D33: Lynnette | E33: Burwood | F33: 18 Cutler road | G33: Oulton | H33: Lowestoft | I33: Suffolk | J33: NR32 3QD | K33: United Kingdom | L33: 07522800227 | M33: lynnetteburwood@gmail.com | N33: Mr & mrs Burwood | P33: Bluecap‚Äôs Nico twist of fate | Q33: AW02706907 | R33: German shepherd dog | S33: Dog | T33: 43650 | U33: 0 | V33: 0 | W33: Not applicable | Y33: Yes | Z33: No | AA33: No
A34: WEST SUFFOLK OBEDIENCE - Sat 30th and Sun 31st May 2026 | B34: 1320 | C34: Mrs | D34: Lynnette | E34: Burwood | F34: 18 Cutler road | G34: Oulton | H34: Lowestoft | I34: Suffolk | J34: NR32 3QD | K34: United Kingdom | L34: 07522800227 | M34: lynnetteburwood@gmail.com | N34: Mr & mrs Burwood | P34: Bluecap‚Äôs Nico twist of fate | Q34: AW02706907 | R34: German shepherd dog | S34: Dog | T34: 43650 | U34: 0 | V34: 0 | W34: Not applicable | Y34: Yes | Z34: No | AA34: No
A35: WEST SUFFOLK OBEDIENCE - Sat 30th and Sun 31st May 2026 | B35: 785 | C35: Ms | D35: Jan | E35: Corr | F35: 13 | G35: Hampton Close | H35: Stevenage | I35: Herts | J35: SG2 8SP | K35: United Kingdom | L35: 07881564577 | M35: janetecorr@aol.com | N35: Mrs J E Corr | P35: Harco's Axi | Q35: AT01194106 | R35: GSD | S35: Bitch | T35: 42450 | U35: 0 | V35: 0 | W35: Not applicable | X35: 1. Camping Friday Night (from Friday mid-day),2. Camping Sat Night | Y35: Yes | Z35: No | AA35: No
A36: WEST SUFFOLK OBEDIENCE - Sat 30th and Sun 31st May 2026 | B36: 785 | C36: Ms | D36: Jan | E36: Corr | F36: 13 | G36: Hampton Close | H36: Stevenage | I36: Herts | J36: SG2 8SP | K36: United Kingdom | L36: 07881564577 | M36: janetecorr@aol.com | N36: Mrs J E Corr | P36: Harco's Axi | Q36: AT01194106 | R36: GSD | S36: Bitch | T36: 42450 | U36: 0 | V36: 0 | W36: Not applicable | X36: 1. Camping Friday Night (from Friday mid-day),2. Camping Sat Night | Y36: Yes | Z36: No | AA36: No
A37: WEST SUFFOLK OBEDIENCE - Sat 30th and Sun 31st May 2026 | B37: 1708 | C37: Mrs | D37: Lynne | E37: Darby | F37: 34 Offenham Close | G37: Church Hill North | H37: Redditch | I37: Worcester | J37: B98 8RJ | K37: United Kingdom | L37: 01527 452562 | M37: lynnedarby@blueyonder.co.uk | N37: Lynne Darby | P37: Mae Eegi Project A EX | Q37: AQ03962203 | R37: Border Collie | S37: Bitch | T37: 41543 | U37: 0 | V37: 0 | W37: Not applicable | X37: 1. Camping Friday Night (from Friday mid-day),2. Camping Sat Night,3. Camping Sunday Night (must be gone by 11:00 am) | Y37: Yes | Z37: No | AA37: No
A38: WEST SUFFOLK OBEDIENCE - Sat 30th and Sun 31st May 2026 | B38: 1708 | C38: Mrs | D38: Lynne | E38: Darby | F38: 34 Offenham Close | G38: Church Hill North | H38: Redditch | I38: Worcester | J38: B98 8RJ | K38: United Kingdom | L38: 01527 452562 | M38: lynnedarby@blueyonder.co.uk | N38: Lynne Darby | P38: Mae Eegi Project A EX | Q38: AQ03962203 | R38: Border Collie | S38: Bitch | T38: 41543 | U38: 0 | V38: 0 | W38: Not applicable | X38: 1. Camping Friday Night (from Friday mid-day),2. Camping Sat Night,3. Camping Sunday Night (must be gone by 11:00 am) | Y38: Yes | Z38: No | AA38: No
A39: WEST SUFFOLK OBEDIENCE - Sat 30th and Sun 31st May 2026 | B39: 2017 | C39: Mrs | D39: Anita | E39: De Klerk | F39: 9 Allington Terrace | G39: Cardinals Green. | H39: Cambridge | I39: Cambridgeshire | J39: CB21 4RF | K39: United Kingdom | L39: 07774213939 | M39: anita.deklerk@btinternet.com | N39: Anita de Klerk | P39: Ashlindt Enya | Q39: AR0902938 | R39: Border Collie | S39: Bitch | T39: 41656 | U39: 0 | V39: 0 | W39: Not applicable | Y39: Yes | Z39: No | AA39: No
A40: WEST SUFFOLK OBEDIENCE - Sat 30th and Sun 31st May 2026 | B40: 2017 | C40: Mrs | D40: Anita | E40: De Klerk | F40: 9 Allington Terrace | G40: Cardinals Green. | H40: Cambridge | I40: Cambridgeshire | J40: CB21 4RF | K40: United Kingdom | L40: 07774213939 | M40: anita.deklerk@btinternet.com | N40: Anita de Klerk | P40: Ashlindt Enya | Q40: AR0902938 | R40: Border Collie | S40: Bitch | T40: 41656 | U40: 0 | V40: 0 | Y40: Yes | Z40: No | AA40: No
...
