Workbook

Sheet Petersfield_&_District_DTS_2025
A1: Show name | B1: Owner Id | E1: Owner title | F1: Owner first name | G1: Owner last name | H1: Owner address 1 | I1: Owner address 2 | J1: Owner town | K1: Owner county | L1: Owner postcode | M1: Owner country | N1: Owner phone | O1: Owner email address | P1: Owner | Q1: Vehicle registration | R1: Registered name | S1: Registered number | T1: Breed | U1: Sex | V1: Date of birth | W1: Merit points | X1: Entered classes | Y1: Preferred judge | Z1: Extras | AA1: Confirmed acceptance of declaration | AB1: Withdraw all entries if balloted out of Championship C | AC1: Show address in catalogue | AD1: Notes to organiser
A2: Petersfield & District DTS - SATUDAY 31ST MAY AND SUNDAY 1ST JUNE 2025 | B2: 2670 | C2: =F2&" "&G2 -> Annie Abbott | D2: =VLOOKUP(R2,'Ring numbers'!G:H,2,FALSE) -> 1 | E2: Miss | F2: Annie | G2: Abbott | H2: Foster cottage | J2: Wareham | K2: Dorset | L2: BH20 7DL | M2: United Kingdom | N2: 7934997677 | O2: anico16@hotmail.com | P2: Annie Abbott | R2: Mosquito Meep | S2: F5-13919-2024 | T2: Toy Poodle | U2: Dog | V2: 45309 | W2: 0 | X2: 2 | AA2: Yes | AB2: No | AC2: No
A3: Petersfield & District DTS - SATUDAY 31ST MAY AND SUNDAY 1ST JUNE 2025 | B3: 2670 | C3: Annie Abbott | D3: 2 | E3: Miss | F3: Annie | G3: Abbott | H3: Foster cottage | J3: Wareham | K3: Dorset | L3: BH20 7DL | M3: United Kingdom | N3: 7934997677 | O3: anico16@hotmail.com | P3: Annie Abbott | R3: Ri Coco the Clown | S3: K159116 | T3: Poodle | U3: Dog | V3: 41476 | W3: 0 | X3: 2 | AA3: Yes | AB3: No | AC3: No
A4: Petersfield & District DTS - SATUDAY 31ST MAY AND SUNDAY 1ST JUNE 2025 | B4: 2649 | C4: Susan Abraham | E4: Miss | F4: Susan | G4: Abraham | H4: 5 Camley Close | J4: Southampton | K4: Hampshire | L4: SO19 9GP | M4: United Kingdom | N4: 023 80432000 | O4: sue_abraham56@hotmail.com | P4: Miss S Abraham | R4: KALIAZAR CRUIZE | S4: AQ01895805 | T4: Border Collie | U4: Dog | V4: 41397 | W4: 0 | X4: 0 | Y4: Not applicable | AA4: Yes | AB4: No | AC4: No
A5: Petersfield & District DTS - SATUDAY 31ST MAY AND SUNDAY 1ST JUNE 2025 | B5: 2649 | C5: Susan Abraham | E5: Miss | F5: Susan | G5: Abraham | H5: 5 Camley Close | J5: Southampton | K5: Hampshire | L5: SO19 9GP | M5: United Kingdom | N5: 023 80432000 | O5: sue_abraham56@hotmail.com | P5: Miss S Abraham | R5: TIPPIVALE JIVE MAN | S5: BB27138202 | T5: BORDER COLLIE | U5: Dog | V5: 45630 | W5: 0 | X5: 0 | Y5: Not applicable | AA5: Yes | AB5: No | AC5: No
A6: Petersfield & District DTS - SATUDAY 31ST MAY AND SUNDAY 1ST JUNE 2025 | B6: 2649 | C6: Susan Abraham | D6: 3 | E6: Miss | F6: Susan | G6: Abraham | H6: 5 Camley Close | J6: Southampton | K6: Hampshire | L6: SO19 9GP | M6: United Kingdom | N6: 023 80432000 | O6: sue_abraham56@hotmail.com | P6: Susan Abraham | R6: Kaliazar Eclipse | S6: AV01178206 | T6: Border Collie | U6: Dog | V6: 43157 | W6: 0 | X6: 4 | Y6: Michelle Richmond | AA6: Yes | AB6: No | AC6: No
A7: Petersfield & District DTS - SATUDAY 31ST MAY AND SUNDAY 1ST JUNE 2025 | B7: 2649 | C7: Susan Abraham | D7: 3 | E7: Miss | F7: Susan | G7: Abraham | H7: 5 Camley Close | J7: Southampton | K7: Hampshire | L7: SO19 9GP | M7: United Kingdom | N7: 023 80432000 | O7: sue_abraham56@hotmail.com | P7: Susan Abraham | R7: Kaliazar Eclipse | S7: AV01178206 | T7: Border Collie | U7: Dog | V7: 43157 | W7: 0 | X7: 5 | Y7: Kathy Case | AA7: Yes | AB7: No | AC7: No
A8: Petersfield & District DTS - SATUDAY 31ST MAY AND SUNDAY 1ST JUNE 2025 | B8: 2649 | C8: Susan Abraham | D8: 3 | E8: Miss | F8: Susan | G8: Abraham | H8: 5 Camley Close | J8: Southampton | K8: Hampshire | L8: SO19 9GP | M8: United Kingdom | N8: 023 80432000 | O8: sue_abraham56@hotmail.com | P8: Susan Abraham | R8: Kaliazar Eclipse | S8: AV01178206 | T8: Border Collie | U8: Dog | V8: 43157 | W8: 0 | X8: 12 | AA8: Yes | AB8: No | AC8: No
A9: Petersfield & District DTS - SATUDAY 31ST MAY AND SUNDAY 1ST JUNE 2025 | B9: 2649 | C9: Susan Abraham | D9: 3 | E9: Miss | F9: Susan | G9: Abraham | H9: 5 Camley Close | J9: Southampton | K9: Hampshire | L9: SO19 9GP | M9: United Kingdom | N9: 023 80432000 | O9: sue_abraham56@hotmail.com | P9: Susan Abraham | R9: Kaliazar Eclipse | S9: AV01178206 | T9: Border Collie | U9: Dog | V9: 43157 | W9: 0 | X9: 14 | AA9: Yes | AB9: No | AC9: No
A10: Petersfield & District DTS - SATUDAY 31ST MAY AND SUNDAY 1ST JUNE 2025 | B10: 2999 | C10: Sandra Aburn | E10: Mrs | F10: Sandra | G10: Aburn | H10: 4 Castle Gardens | J10: Dorking | K10: Surrey | L10: RH4 1NY | M10: United Kingdom | N10: 7852469499 | O10: sandra1.bailey@icloud.com | P10: Miss S Bailey | R10: Forevermagic road king | S10: K0273807 | T10: Working sheepdog | U10: Dog | V10: 45263 | W10: 0 | X10: 0 | Y10: Not applicable | AA10: Yes | AB10: No | AC10: No
A11: Petersfield & District DTS - SATUDAY 31ST MAY AND SUNDAY 1ST JUNE 2025 | B11: 2999 | C11: Sandra Aburn | D11: 4 | E11: Mrs | F11: Sandra | G11: Aburn | H11: 4 Castle Gardens | J11: Dorking | K11: Surrey | L11: RH4 1NY | M11: United Kingdom | N11: 7852469499 | O11: sandra1.bailey@icloud.com | P11: Sandra Bailey | R11: Sapphire Inferno Sky | S11: K164665 | T11: Working Sheepdog | U11: Bitch | V11: 43211 | W11: 0 | X11: 5 | Y11: Kathy Case | AA11: Yes | AB11: No | AC11: No
A12: Petersfield & District DTS - SATUDAY 31ST MAY AND SUNDAY 1ST JUNE 2025 | B12: 2999 | C12: Sandra Aburn | D12: 4 | E12: Mrs | F12: Sandra | G12: Aburn | H12: 4 Castle Gardens | J12: Dorking | K12: Surrey | L12: RH4 1NY | M12: United Kingdom | N12: 7852469499 | O12: sandra1.bailey@icloud.com | P12: Sandra Bailey | R12: Sapphire Inferno Sky | S12: K164665 | T12: Working Sheepdog | U12: Bitch | V12: 43211 | W12: 0 | X12: 6 | Y12: Sue Monk | AA12: Yes | AB12: No | AC12: No
A13: Petersfield & District DTS - SATUDAY 31ST MAY AND SUNDAY 1ST JUNE 2025 | B13: 2999 | C13: Sandra Aburn | E13: Mrs | F13: Sandra | G13: Aburn | H13: 4 Castle Gardens | J13: Dorking | K13: Surrey | L13: RH4 1NY | M13: United Kingdom | N13: 7852469499 | O13: sandra1.bailey@icloud.com | P13: Miss S Bailey | R13: Forevermagic road king | S13: K0273807 | T13: Working sheepdog | U13: Dog | V13: 45263 | W13: 0 | X13: 0 | Y13: Not applicable | AA13: Yes | AB13: No | AC13: No
A14: Petersfield & District DTS - SATUDAY 31ST MAY AND SUNDAY 1ST JUNE 2025 | B14: 2999 | C14: Sandra Aburn | D14: 4 | E14: Mrs | F14: Sandra | G14: Aburn | H14: 4 Castle Gardens | J14: Dorking | K14: Surrey | L14: RH4 1NY | M14: United Kingdom | N14: 7852469499 | O14: sandra1.bailey@icloud.com | P14: Sandra Bailey | R14: Sapphire Inferno Sky | S14: K164665 | T14: Working Sheepdog | U14: Bitch | V14: 43211 | W14: 0 | X14: 15 | AA14: Yes | AB14: No | AC14: No
A15: Petersfield & District DTS - SATUDAY 31ST MAY AND SUNDAY 1ST JUNE 2025 | B15: 2999 | C15: Sandra Aburn | D15: 4 | E15: Mrs | F15: Sandra | G15: Aburn | H15: 4 Castle Gardens | J15: Dorking | K15: Surrey | L15: RH4 1NY | M15: United Kingdom | N15: 7852469499 | O15: sandra1.bailey@icloud.com | P15: Sandra Bailey | R15: Sapphire Inferno Sky | S15: K164665 | T15: Working Sheepdog | U15: Bitch | V15: 43211 | W15: 0 | X15: 17 | AA15: Yes | AB15: No | AC15: No
A16: Petersfield & District DTS - SATUDAY 31ST MAY AND SUNDAY 1ST JUNE 2025 | B16: 2387 | C16: Janet Aldridge | D16: 8 | E16: Mrs | F16: Janet | G16: Aldridge | H16: 2 Malabar farm Cottages, Badby Road West | J16: Daventry | K16: Northants | L16: NN114NH | M16: United Kingdom | N16: 447970863728 | O16: johnmalabar@hotmail.com | P16: Janet Aldridge | R16: Malaridge Sappire Sunset | S16: KO271139 | T16: Working Sheepdog | U16: Bitch | V16: 44971 | W16: 0 | X16: 13 | AA16: Yes | AB16: No | AC16: No
A17: Petersfield & District DTS - SATUDAY 31ST MAY AND SUNDAY 1ST JUNE 2025 | B17: 2387 | C17: Janet Aldridge | D17: 9 | E17: Mrs | F17: Janet | G17: Aldridge | H17: 2 Malabar farm Cottages, Badby Road West | J17: Daventry | K17: Northants | L17: NN114NH | M17: United Kingdom | N17: 447970863728 | O17: johnmalabar@hotmail.com | P17: Janet Aldridge | R17: Tigrys Treacle Tart at Malaridge | S17: K0261529 | T17: Working Sheepdog | U17: Bitch | V17: 44058 | W17: 0 | X17: 17 | AA17: Yes | AB17: No | AC17: No
A18: Petersfield & District DTS - SATUDAY 31ST MAY AND SUNDAY 1ST JUNE 2025 | B18: 2387 | C18: Janet Aldridge | D18: 6 | E18: Mrs | F18: Janet | G18: Aldridge | H18: 2 Malabar farm Cottages, Badby Road West | J18: Daventry | K18: Northants | L18: NN114NH | M18: United Kingdom | N18: 447970863728 | O18: johnmalabar@hotmail.com | P18: Janet Aldridge | R18: Malaridge Dark Side of Moon | S18: KO261404 | T18: Working Sheepdog | U18: Dog | V18: 44106 | W18: 0 | X18: 18 | AA18: Yes | AB18: No | AC18: No
A19: Petersfield & District DTS - SATUDAY 31ST MAY AND SUNDAY 1ST JUNE 2025 | B19: 2387 | C19: Janet Aldridge | D19: 5 | E19: Mrs | F19: Janet | G19: Aldridge | H19: 2 Malabar farm Cottages, Badby Road West | J19: Daventry | K19: Northants | L19: NN114NH | M19: United Kingdom | N19: 447970863728 | O19: johnmalabar@hotmail.com | P19: Janet Aldridge | R19: Candlewind Cassanova at Malaridge | S19: AU01669807 | T19: Border Collie | U19: Dog | V19: 42810 | W19: 0 | X19: 18 | AA19: Yes | AB19: No | AC19: No
A20: Petersfield & District DTS - SATUDAY 31ST MAY AND SUNDAY 1ST JUNE 2025 | B20: 2387 | C20: Janet Aldridge | D20: 7 | E20: Mrs | F20: Janet | G20: Aldridge | H20: 2 Malabar farm Cottages, Badby Road West | J20: Daventry | K20: Northants | L20: NN114NH | M20: United Kingdom | N20: 447970863728 | O20: johnmalabar@hotmail.com | P20: Janet Aldridge | R20: Malaridge Poachers Moon | S20: K159039 | T20: Working Sheepdog | U20: Bitch | V20: 42996 | W20: 0 | X20: 19 | AA20: Yes | AB20: No | AC20: No
A21: Petersfield & District DTS - SATUDAY 31ST MAY AND SUNDAY 1ST JUNE 2025 | B21: 1500 | C21: Kay Allen | D21: 10 | E21: Mrs | F21: Kay | G21: Allen | H21: Maxworthy Barn | I21: Maxworthy | J21: Launceston | K21: Devon | L21: PL15 8LZ | M21: United Kingdom | N21: 1566785587 | O21: kay.allen41@gmail.com | P21: Kay Allen | R21: Torlake Red Nov Ex | S21: AW00031601 | T21: Border Collie | U21: Dog | V21: 43422 | W21: 0 | X21: 5 | Y21: Kathy Case | AA21: Yes | AB21: No | AC21: Yes | AE21: Judging Ch C Bitch Sunday. Camping required Friday-Monday please. _x000D_ Steward Sue Garner
A22: Petersfield & District DTS - SATUDAY 31ST MAY AND SUNDAY 1ST JUNE 2025 | B22: 1500 | C22: Kay Allen | E22: Mrs | F22: Kay | G22: Allen | H22: Maxworthy Barn | I22: Maxworthy | J22: Launceston | K22: Devon | L22: PL15 8LZ | M22: United Kingdom | N22: 1566785587 | O22: kay.allen41@gmail.com | P22: Kay Allen | R22: Cories Crystal Lake B Ex AW(B) | S22: AR02059805 | T22: Border Collie | U22: Bitch | V22: 41709 | W22: 0 | X22: 0 | Y22: Not applicable | AA22: Yes | AB22: No | AC22: Yes | AD22: Judging Ch C Bitch Sunday. Camping required Friday-Monday please. _x000D_ Steward Sue Garner
A23: Petersfield & District DTS - SATUDAY 31ST MAY AND SUNDAY 1ST JUNE 2025 | B23: 1500 | C23: Kay Allen | E23: Mrs | F23: Kay | G23: Allen | H23: Maxworthy Barn | I23: Maxworthy | J23: Launceston | K23: Devon | L23: PL15 8LZ | M23: United Kingdom | N23: 1566785587 | O23: kay.allen41@gmail.com | P23: Kay Allen | R23: Torlake Becka | S23: AW00031602 | T23: Border Collie | U23: Bitch | V23: 43422 | W23: 0 | X23: 0 | Y23: Not applicable | AA23: Yes | AB23: No | AC23: Yes | AD23: Judging Ch C Bitch Sunday. Camping required Friday-Monday please. _x000D_ Steward Sue Garner
A24: Petersfield & District DTS - SATUDAY 31ST MAY AND SUNDAY 1ST JUNE 2025 | B24: 1500 | C24: Kay Allen | E24: Mrs | F24: Kay | G24: Allen | H24: Maxworthy Barn | I24: Maxworthy | J24: Launceston | K24: Devon | L24: PL15 8LZ | M24: United Kingdom | N24: 1566785587 | O24: kay.allen41@gmail.com | P24: Kay Allen | R24: Torlake Royal A ex | S24: AU00564401 | T24: Border Collie | U24: Dog | V24: 42744 | W24: 0 | X24: 0 | Y24: Not applicable | AA24: Yes | AB24: No | AC24: Yes | AD24: Judging Ch C Bitch Sunday. Camping required Friday-Monday please. _x000D_ Steward Sue Garner
A25: Petersfield & District DTS - SATUDAY 31ST MAY AND SUNDAY 1ST JUNE 2025 | B25: 1500 | C25: Kay Allen | E25: Mrs | F25: Kay | G25: Allen | H25: Maxworthy Barn | I25: Maxworthy | J25: Launceston | K25: Devon | L25: PL15 8LZ | M25: United Kingdom | N25: 1566785587 | O25: kay.allen41@gmail.com | P25: Kay Allen | R25: Torlake Temple | S25: BA18655305 | T25: Border Collie | U25: Bitch | V25: 44931 | W25: 0 | X25: 0 | Y25: Not applicable | AA25: Yes | AB25: No | AC25: Yes | AD25: Judging Ch C Bitch Sunday. Camping required Friday-Monday please. _x000D_ Steward Sue Garner
A26: Petersfield & District DTS - SATUDAY 31ST MAY AND SUNDAY 1ST JUNE 2025 | B26: 1500 | C26: Kay Allen | E26: Mrs | F26: Kay | G26: Allen | H26: Maxworthy Barn | I26: Maxworthy | J26: Launceston | K26: Devon | L26: PL15 8LZ | M26: United Kingdom | N26: 1566785587 | O26: kay.allen41@gmail.com | P26: Kay Allen | R26: Torlake Becka | S26: AW00031602 | T26: Border Collie | U26: Bitch | V26: 43422 | W26: 0 | X26: 0 | Y26: Not applicable | AA26: Yes | AB26: No | AC26: Yes | AD26: Judging Ch C Bitch Sunday. Camping required Friday-Monday please. _x000D_ Steward Sue Garner
A27: Petersfield & District DTS - SATUDAY 31ST MAY AND SUNDAY 1ST JUNE 2025 | B27: 1500 | C27: Kay Allen | E27: Mrs | F27: Kay | G27: Allen | H27: Maxworthy Barn | I27: Maxworthy | J27: Launceston | K27: Devon | L27: PL15 8LZ | M27: United Kingdom | N27: 1566785587 | O27: kay.allen41@gmail.com | P27: Kay Allen | R27: Torlake Red Nov Ex | S27: AW00031601 | T27: Border Collie | U27: Dog | V27: 43422 | W27: 0 | X27: 0 | Y27: Not applicable | AA27: Yes | AB27: No | AC27: Yes | AD27: Judging Ch C Bitch Sunday. Camping required Friday-Monday please. _x000D_ Steward Sue Garner
A28: Petersfield & District DTS - SATUDAY 31ST MAY AND SUNDAY 1ST JUNE 2025 | B28: 1500 | C28: Kay Allen | E28: Mrs | F28: Kay | G28: Allen | H28: Maxworthy Barn | I28: Maxworthy | J28: Launceston | K28: Devon | L28: PL15 8LZ | M28: United Kingdom | N28: 1566785587 | O28: kay.allen41@gmail.com | P28: Kay Allen | R28: Torlake Royal A ex | S28: AU00564401 | T28: Border Collie | U28: Dog | V28: 42744 | W28: 0 | X28: 0 | Y28: Not applicable | AA28: Yes | AB28: No | AC28: Yes | AD28: Judging Ch C Bitch Sunday. Camping required Friday-Monday please. _x000D_ Steward Sue Garner
A29: Petersfield & District DTS - SATUDAY 31ST MAY AND SUNDAY 1ST JUNE 2025 | B29: 1500 | C29: Kay Allen | E29: Mrs | F29: Kay | G29: Allen | H29: Maxworthy Barn | I29: Maxworthy | J29: Launceston | K29: Devon | L29: PL15 8LZ | M29: United Kingdom | N29: 1566785587 | O29: kay.allen41@gmail.com | P29: Kay Allen | R29: Cories Crystal Lake B Ex AW(B) | S29: AR02059805 | T29: Border Collie | U29: Bitch | V29: 41709 | W29: 0 | X29: 0 | Y29: Not applicable | AA29: Yes | AB29: No | AC29: Yes | AD29: Judging Ch C Bitch Sunday. Camping required Friday-Monday please. _x000D_ Steward Sue Garner
A30: Petersfield & District DTS - SATUDAY 31ST MAY AND SUNDAY 1ST JUNE 2025 | B30: 1500 | C30: Kay Allen | E30: Mrs | F30: Kay | G30: Allen | H30: Maxworthy Barn | I30: Maxworthy | J30: Launceston | K30: Devon | L30: PL15 8LZ | M30: United Kingdom | N30: 1566785587 | O30: kay.allen41@gmail.com | P30: Kay Allen | R30: Torlake Temple | S30: BA18655305 | T30: Border Collie | U30: Bitch | V30: 44931 | W30: 0 | X30: 0 | Y30: Not applicable | AA30: Yes | AB30: No | AC30: Yes | AD30: Judging Ch C Bitch Sunday. Camping required Friday-Monday please. _x000D_ Steward Sue Garner
A31: Petersfield & District DTS - SATUDAY 31ST MAY AND SUNDAY 1ST JUNE 2025 | B31: 701 | C31: Tracy Ansell | D31: 11 | E31: Mrs | F31: Tracy | G31: Ansell | H31: 9 Bates close | J31: HIGHAM FERRES | K31: NORTHANTS | L31: NN10 8HF | M31: United Kingdom | N31: 1933353038 | O31: srallebone9@gmail.com | P31: Tracy Ansell | R31: Buskru Go With the Flo | S31: naf | T31: Crossbreed | U31: Bitch | V31: 44890 | W31: 0 | X31: 4 | Y31: Michelle Richmond | Z31: Camping - Friday night,Camping - Saturday night | AA31: Yes | AB31: No | AC31: No
A32: Petersfield & District DTS - SATUDAY 31ST MAY AND SUNDAY 1ST JUNE 2025 | B32: 701 | C32: Tracy Ansell | D32: 13 | E32: Mrs | F32: Tracy | G32: Ansell | H32: 9 Bates close | J32: HIGHAM FERRES | K32: NORTHANTS | L32: NN10 8HF | M32: United Kingdom | N32: 1933353038 | O32: srallebone9@gmail.com | P32: Tracy Ansell | R32: Tazziemin Strike a Pose for Chalkwell | S32: AZ15444205 | T32: Standard Poodle | U32: Bitch | V32: 44754 | W32: 0 | X32: 6 | Y32: Sue Monk | Z32: Camping - Friday night,Camping - Saturday night | AA32: Yes | AB32: No | AC32: No
A33: Petersfield & District DTS - SATUDAY 31ST MAY AND SUNDAY 1ST JUNE 2025 | B33: 701 | C33: Tracy Ansell | D33: 13 | E33: Mrs | F33: Tracy | G33: Ansell | H33: 9 Bates close | J33: HIGHAM FERRES | K33: NORTHANTS | L33: NN10 8HF | M33: United Kingdom | N33: 1933353038 | O33: srallebone9@gmail.com | P33: Tracy Ansell | R33: Tazziemin Strike a Pose for Chalkwell | S33: AZ15444205 | T33: Standard Poodle | U33: Bitch | V33: 44754 | W33: 0 | X33: 5 | Y33: Kathy Case | Z33: Camping - Friday night,Camping - Saturday night | AA33: Yes | AB33: No | AC33: No
A34: Petersfield & District DTS - SATUDAY 31ST MAY AND SUNDAY 1ST JUNE 2025 | B34: 701 | C34: Tracy Ansell | D34: 12 | E34: Mrs | F34: Tracy | G34: Ansell | H34: 9 Bates close | J34: HIGHAM FERRES | K34: NORTHANTS | L34: NN10 8HF | M34: United Kingdom | N34: 1933353038 | O34: srallebone9@gmail.com | P34: Tracy Ansell | R34: Chalkwell Worth a Shot | S34: AU00900601 | T34: Standard Poodle | U34: Dog | V34: 42657 | W34: 0 | X34: 7 | Z34: Camping - Friday night,Camping - Saturday night | AA34: Yes | AB34: No | AC34: No
A35: Petersfield & District DTS - SATUDAY 31ST MAY AND SUNDAY 1ST JUNE 2025 | B35: 701 | C35: Tracy Ansell | D35: 11 | E35: Mrs | F35: Tracy | G35: Ansell | H35: 9 Bates close | J35: HIGHAM FERRES | K35: NORTHANTS | L35: NN10 8HF | M35: United Kingdom | N35: 1933353038 | O35: srallebone9@gmail.com | P35: Tracy Ansell | R35: Buskru Go With the Flo | S35: naf | T35: Crossbreed | U35: Bitch | V35: 44890 | W35: 0 | X35: 13 | Z35: Camping - Friday night,Camping - Saturday night | AA35: Yes | AB35: No | AC35: No
A36: Petersfield & District DTS - SATUDAY 31ST MAY AND SUNDAY 1ST JUNE 2025 | B36: 701 | C36: Tracy Ansell | D36: 13 | E36: Mrs | F36: Tracy | G36: Ansell | H36: 9 Bates close | J36: HIGHAM FERRES | K36: NORTHANTS | L36: NN10 8HF | M36: United Kingdom | N36: 1933353038 | O36: srallebone9@gmail.com | P36: Tracy Ansell | R36: Tazziemin Strike a Pose for Chalkwell | S36: AZ15444205 | T36: Standard Poodle | U36: Bitch | V36: 44754 | W36: 0 | X36: 15 | Z36: Camping - Friday night,Camping - Saturday night | AA36: Yes | AB36: No | AC36: No
A37: Petersfield & District DTS - SATUDAY 31ST MAY AND SUNDAY 1ST JUNE 2025 | B37: 701 | C37: Tracy Ansell | D37: 13 | E37: Mrs | F37: Tracy | G37: Ansell | H37: 9 Bates close | J37: HIGHAM FERRES | K37: NORTHANTS | L37: NN10 8HF | M37: United Kingdom | N37: 1933353038 | O37: srallebone9@gmail.com | P37: Tracy Ansell | R37: Tazziemin Strike a Pose for Chalkwell | S37: AZ15444205 | T37: Standard Poodle | U37: Bitch | V37: 44754 | W37: 0 | X37: 17 | Z37: Camping - Friday night,Camping - Saturday night | AA37: Yes | AB37: No | AC37: No
A38: Petersfield & District DTS - SATUDAY 31ST MAY AND SUNDAY 1ST JUNE 2025 | B38: 701 | C38: Tracy Ansell | D38: 12 | E38: Mrs | F38: Tracy | G38: Ansell | H38: 9 Bates close | J38: HIGHAM FERRES | K38: NORTHANTS | L38: NN10 8HF | M38: United Kingdom | N38: 1933353038 | O38: srallebone9@gmail.com | P38: Tracy Ansell | R38: Chalkwell Worth a Shot | S38: AU00900601 | T38: Standard Poodle | U38: Dog | V38: 42657 | W38: 0 | X38: 20 | Z38: Camping - Friday night,Camping - Saturday night | AA38: Yes | AB38: No | AC38: No
A39: Petersfield & District DTS - SATUDAY 31ST MAY AND SUNDAY 1ST JUNE 2025 | B39: 701 | C39: Tracy Ansell | E39: Mrs | F39: Tracy | G39: Ansell | H39: 9 Bates close | J39: HIGHAM FERRES | K39: NORTHANTS | L39: NN10 8HF | M39: United Kingdom | N39: 1933353038 | O39: srallebone9@gmail.com | P39: Mrs Tracy Ansell | R39: CH Chalkwell Express Yourself | S39: AP01851801 | T39: Standard Poodle | U39: Dog | V39: 41005 | W39: 0 | X39: 0 | Y39: Not applicable | Z39: Camping - Friday night,Camping - Saturday night | AA39: Yes | AB39: No | AC39: No
A40: Petersfield & District DTS - SATUDAY 31ST MAY AND SUNDAY 1ST JUNE 2025 | B40: 701 | C40: Tracy Ansell | E40: Mrs | F40: Tracy | G40: Ansell | H40: 9 Bates close | J40: HIGHAM FERRES | K40: NORTHANTS | L40: NN10 8HF | M40: United Kingdom | N40: 1933353038 | O40: srallebone9@gmail.com | P40: Mrs Tracy Ansell | R40: Somanic pop the cork for Chalkwell | S40: AW02417801 | T40: standard poodle | U40: Bitch | V40: 43595 | W40: 0 | X40: 0 | Y40: Not applicable | Z40: Camping - Friday night,Camping - Saturday night | AA40: Yes | AB40: No | AC40: No
...

Sheet Petersfield_&_District_DTS_ (2)
A1: Show name | B1: Owner Id | E1: Owner title | F1: Owner first name | G1: Owner last name | H1: Owner address 1 | I1: Owner address 2 | J1: Owner town | K1: Owner county | L1: Owner postcode | M1: Owner country | N1: Owner phone | O1: Owner email address | P1: Owner registered name | Q1: Vehicle registration | R1: Registered name | S1: Registered number | T1: Breed | U1: Sex | V1: Date of birth | W1: Merit points | X1: Entered classes | Y1: Preferred judge | Z1: Extras | AA1: Confirmed acceptance of declaration | AB1: Withdraw all entries if balloted out of Championship C | AC1: Show address in catalogue | AD1: Notes to organiser
A2: Petersfield & District DTS - SATUDAY 31ST MAY AND SUNDAY 1ST JUNE 2025 | B2: 2670 | C2: =F2&" "&G2 -> Annie Abbott | D2: =VLOOKUP(R2,'Ring numbers'!G:H,2,FALSE) -> 1 | E2: Miss | F2: Annie | G2: Abbott | H2: Foster cottage | J2: Wareham | K2: Dorset | L2: BH20 7DL | M2: United Kingdom | N2: 7934997677 | O2: anico16@hotmail.com | P2: Annie Abbott | R2: Mosquito Meep | S2: F5-13919-2024 | T2: Toy Poodle | U2: Dog | V2: 45309 | W2: 0 | X2: 2 | AA2: Yes | AB2: No | AC2: No
A3: Petersfield & District DTS - SATUDAY 31ST MAY AND SUNDAY 1ST JUNE 2025 | B3: 2670 | C3: Annie Abbott | D3: 2 | E3: Miss | F3: Annie | G3: Abbott | H3: Foster cottage | J3: Wareham | K3: Dorset | L3: BH20 7DL | M3: United Kingdom | N3: 7934997677 | O3: anico16@hotmail.com | P3: Annie Abbott | R3: Ri Coco the Clown | S3: K159116 | T3: Poodle | U3: Dog | V3: 41476 | W3: 0 | X3: 2 | AA3: Yes | AB3: No | AC3: No
A4: Petersfield & District DTS - SATUDAY 31ST MAY AND SUNDAY 1ST JUNE 2025 | B4: 2649 | C4: Susan Abraham | E4: Miss | F4: Susan | G4: Abraham | H4: 5 Camley Close | J4: Southampton | K4: Hampshire | L4: SO19 9GP | M4: United Kingdom | N4: 023 80432000 | O4: sue_abraham56@hotmail.com | P4: Miss S Abraham | R4: KALIAZAR CRUIZE | S4: AQ01895805 | T4: Border Collie | U4: Dog | V4: 41397 | W4: 0 | X4: 0 | Y4: Not applicable | AA4: Yes | AB4: No | AC4: No
A5: Petersfield & District DTS - SATUDAY 31ST MAY AND SUNDAY 1ST JUNE 2025 | B5: 2649 | C5: Susan Abraham | E5: Miss | F5: Susan | G5: Abraham | H5: 5 Camley Close | J5: Southampton | K5: Hampshire | L5: SO19 9GP | M5: United Kingdom | N5: 023 80432000 | O5: sue_abraham56@hotmail.com | P5: Miss S Abraham | R5: TIPPIVALE JIVE MAN | S5: BB27138202 | T5: BORDER COLLIE | U5: Dog | V5: 45630 | W5: 0 | X5: 0 | Y5: Not applicable | AA5: Yes | AB5: No | AC5: No
A6: Petersfield & District DTS - SATUDAY 31ST MAY AND SUNDAY 1ST JUNE 2025 | B6: 2649 | C6: Susan Abraham | D6: 3 | E6: Miss | F6: Susan | G6: Abraham | H6: 5 Camley Close | J6: Southampton | K6: Hampshire | L6: SO19 9GP | M6: United Kingdom | N6: 023 80432000 | O6: sue_abraham56@hotmail.com | P6: Susan Abraham | R6: Kaliazar Eclipse | S6: AV01178206 | T6: Border Collie | U6: Dog | V6: 43157 | W6: 0 | X6: 4 | Y6: Michelle Richmond | AA6: Yes | AB6: No | AC6: No
A7: Petersfield & District DTS - SATUDAY 31ST MAY AND SUNDAY 1ST JUNE 2025 | B7: 2649 | C7: Susan Abraham | D7: 3 | E7: Miss | F7: Susan | G7: Abraham | H7: 5 Camley Close | J7: Southampton | K7: Hampshire | L7: SO19 9GP | M7: United Kingdom | N7: 023 80432000 | O7: sue_abraham56@hotmail.com | P7: Susan Abraham | R7: Kaliazar Eclipse | S7: AV01178206 | T7: Border Collie | U7: Dog | V7: 43157 | W7: 0 | X7: 5 | Y7: Kathy Case | AA7: Yes | AB7: No | AC7: No
A8: Petersfield & District DTS - SATUDAY 31ST MAY AND SUNDAY 1ST JUNE 2025 | B8: 2649 | C8: Susan Abraham | D8: 3 | E8: Miss | F8: Susan | G8: Abraham | H8: 5 Camley Close | J8: Southampton | K8: Hampshire | L8: SO19 9GP | M8: United Kingdom | N8: 023 80432000 | O8: sue_abraham56@hotmail.com | P8: Susan Abraham | R8: Kaliazar Eclipse | S8: AV01178206 | T8: Border Collie | U8: Dog | V8: 43157 | W8: 0 | X8: 12 | AA8: Yes | AB8: No | AC8: No
A9: Petersfield & District DTS - SATUDAY 31ST MAY AND SUNDAY 1ST JUNE 2025 | B9: 2649 | C9: Susan Abraham | D9: 3 | E9: Miss | F9: Susan | G9: Abraham | H9: 5 Camley Close | J9: Southampton | K9: Hampshire | L9: SO19 9GP | M9: United Kingdom | N9: 023 80432000 | O9: sue_abraham56@hotmail.com | P9: Susan Abraham | R9: Kaliazar Eclipse | S9: AV01178206 | T9: Border Collie | U9: Dog | V9: 43157 | W9: 0 | X9: 14 | AA9: Yes | AB9: No | AC9: No
A10: Petersfield & District DTS - SATUDAY 31ST MAY AND SUNDAY 1ST JUNE 2025 | B10: 2999 | C10: Sandra Aburn | E10: Mrs | F10: Sandra | G10: Aburn | H10: 4 Castle Gardens | J10: Dorking | K10: Surrey | L10: RH4 1NY | M10: United Kingdom | N10: 7852469499 | O10: sandra1.bailey@icloud.com | P10: Miss S Bailey | R10: Forevermagic road king | S10: K0273807 | T10: Working sheepdog | U10: Dog | V10: 45263 | W10: 0 | X10: 0 | Y10: Not applicable | AA10: Yes | AB10: No | AC10: No
A11: Petersfield & District DTS - SATUDAY 31ST MAY AND SUNDAY 1ST JUNE 2025 | B11: 2999 | C11: Sandra Aburn | D11: 4 | E11: Mrs | F11: Sandra | G11: Aburn | H11: 4 Castle Gardens | J11: Dorking | K11: Surrey | L11: RH4 1NY | M11: United Kingdom | N11: 7852469499 | O11: sandra1.bailey@icloud.com | P11: Sandra Bailey | R11: Sapphire Inferno Sky | S11: K164665 | T11: Working Sheepdog | U11: Bitch | V11: 43211 | W11: 0 | X11: 5 | Y11: Kathy Case | AA11: Yes | AB11: No | AC11: No
A12: Petersfield & District DTS - SATUDAY 31ST MAY AND SUNDAY 1ST JUNE 2025 | B12: 2999 | C12: Sandra Aburn | D12: 4 | E12: Mrs | F12: Sandra | G12: Aburn | H12: 4 Castle Gardens | J12: Dorking | K12: Surrey | L12: RH4 1NY | M12: United Kingdom | N12: 7852469499 | O12: sandra1.bailey@icloud.com | P12: Sandra Bailey | R12: Sapphire Inferno Sky | S12: K164665 | T12: Working Sheepdog | U12: Bitch | V12: 43211 | W12: 0 | X12: 6 | Y12: Sue Monk | AA12: Yes | AB12: No | AC12: No
A13: Petersfield & District DTS - SATUDAY 31ST MAY AND SUNDAY 1ST JUNE 2025 | B13: 2999 | C13: Sandra Aburn | E13: Mrs | F13: Sandra | G13: Aburn | H13: 4 Castle Gardens | J13: Dorking | K13: Surrey | L13: RH4 1NY | M13: United Kingdom | N13: 7852469499 | O13: sandra1.bailey@icloud.com | P13: Miss S Bailey | R13: Forevermagic road king | S13: K0273807 | T13: Working sheepdog | U13: Dog | V13: 45263 | W13: 0 | X13: 0 | Y13: Not applicable | AA13: Yes | AB13: No | AC13: No
A14: Petersfield & District DTS - SATUDAY 31ST MAY AND SUNDAY 1ST JUNE 2025 | B14: 2999 | C14: Sandra Aburn | D14: 4 | E14: Mrs | F14: Sandra | G14: Aburn | H14: 4 Castle Gardens | J14: Dorking | K14: Surrey | L14: RH4 1NY | M14: United Kingdom | N14: 7852469499 | O14: sandra1.bailey@icloud.com | P14: Sandra Bailey | R14: Sapphire Inferno Sky | S14: K164665 | T14: Working Sheepdog | U14: Bitch | V14: 43211 | W14: 0 | X14: 15 | AA14: Yes | AB14: No | AC14: No
A15: Petersfield & District DTS - SATUDAY 31ST MAY AND SUNDAY 1ST JUNE 2025 | B15: 2999 | C15: Sandra Aburn | D15: 4 | E15: Mrs | F15: Sandra | G15: Aburn | H15: 4 Castle Gardens | J15: Dorking | K15: Surrey | L15: RH4 1NY | M15: United Kingdom | N15: 7852469499 | O15: sandra1.bailey@icloud.com | P15: Sandra Bailey | R15: Sapphire Inferno Sky | S15: K164665 | T15: Working Sheepdog | U15: Bitch | V15: 43211 | W15: 0 | X15: 17 | AA15: Yes | AB15: No | AC15: No
A16: Petersfield & District DTS - SATUDAY 31ST MAY AND SUNDAY 1ST JUNE 2025 | B16: 2387 | C16: Janet Aldridge | D16: 8 | E16: Mrs | F16: Janet | G16: Aldridge | H16: 2 Malabar farm Cottages, Badby Road West | J16: Daventry | K16: Northants | L16: NN114NH | M16: United Kingdom | N16: 447970863728 | O16: johnmalabar@hotmail.com | P16: Janet Aldridge | R16: Malaridge Sappire Sunset | S16: KO271139 | T16: Working Sheepdog | U16: Bitch | V16: 44971 | W16: 0 | X16: 13 | AA16: Yes | AB16: No | AC16: No
A17: Petersfield & District DTS - SATUDAY 31ST MAY AND SUNDAY 1ST JUNE 2025 | B17: 2387 | C17: Janet Aldridge | D17: 9 | E17: Mrs | F17: Janet | G17: Aldridge | H17: 2 Malabar farm Cottages, Badby Road West | J17: Daventry | K17: Northants | L17: NN114NH | M17: United Kingdom | N17: 447970863728 | O17: johnmalabar@hotmail.com | P17: Janet Aldridge | R17: Tigrys Treacle Tart at Malaridge | S17: K0261529 | T17: Working Sheepdog | U17: Bitch | V17: 44058 | W17: 0 | X17: 17 | AA17: Yes | AB17: No | AC17: No
A18: Petersfield & District DTS - SATUDAY 31ST MAY AND SUNDAY 1ST JUNE 2025 | B18: 2387 | C18: Janet Aldridge | D18: 6 | E18: Mrs | F18: Janet | G18: Aldridge | H18: 2 Malabar farm Cottages, Badby Road West | J18: Daventry | K18: Northants | L18: NN114NH | M18: United Kingdom | N18: 447970863728 | O18: johnmalabar@hotmail.com | P18: Janet Aldridge | R18: Malaridge Dark Side of Moon | S18: KO261404 | T18: Working Sheepdog | U18: Dog | V18: 44106 | W18: 0 | X18: 18 | AA18: Yes | AB18: No | AC18: No
A19: Petersfield & District DTS - SATUDAY 31ST MAY AND SUNDAY 1ST JUNE 2025 | B19: 2387 | C19: Janet Aldridge | D19: 5 | E19: Mrs | F19: Janet | G19: Aldridge | H19: 2 Malabar farm Cottages, Badby Road West | J19: Daventry | K19: Northants | L19: NN114NH | M19: United Kingdom | N19: 447970863728 | O19: johnmalabar@hotmail.com | P19: Janet Aldridge | R19: Candlewind Cassanova at Malaridge | S19: AU01669807 | T19: Border Collie | U19: Dog | V19: 42810 | W19: 0 | X19: 18 | AA19: Yes | AB19: No | AC19: No
A20: Petersfield & District DTS - SATUDAY 31ST MAY AND SUNDAY 1ST JUNE 2025 | B20: 2387 | C20: Janet Aldridge | D20: 7 | E20: Mrs | F20: Janet | G20: Aldridge | H20: 2 Malabar farm Cottages, Badby Road West | J20: Daventry | K20: Northants | L20: NN114NH | M20: United Kingdom | N20: 447970863728 | O20: johnmalabar@hotmail.com | P20: Janet Aldridge | R20: Malaridge Poachers Moon | S20: K159039 | T20: Working Sheepdog | U20: Bitch | V20: 42996 | W20: 0 | X20: 19 | AA20: Yes | AB20: No | AC20: No
A21: Petersfield & District DTS - SATUDAY 31ST MAY AND SUNDAY 1ST JUNE 2025 | B21: 1500 | C21: Kay Allen | D21: 10 | E21: Mrs | F21: Kay | G21: Allen | H21: Maxworthy Barn | I21: Maxworthy | J21: Launceston | K21: Devon | L21: PL15 8LZ | M21: United Kingdom | N21: 1566785587 | O21: kay.allen41@gmail.com | P21: Kay Allen | R21: Torlake Red Nov Ex | S21: AW00031601 | T21: Border Collie | U21: Dog | V21: 43422 | W21: 0 | X21: 5 | Y21: Kathy Case | AA21: Yes | AB21: No | AC21: Yes | AE21: Judging Ch C Bitch Sunday. Camping required Friday-Monday please. _x000D_ Steward Sue Garner
A22: Petersfield & District DTS - SATUDAY 31ST MAY AND SUNDAY 1ST JUNE 2025 | B22: 1500 | C22: Kay Allen | E22: Mrs | F22: Kay | G22: Allen | H22: Maxworthy Barn | I22: Maxworthy | J22: Launceston | K22: Devon | L22: PL15 8LZ | M22: United Kingdom | N22: 1566785587 | O22: kay.allen41@gmail.com | P22: Kay Allen | R22: Cories Crystal Lake B Ex AW(B) | S22: AR02059805 | T22: Border Collie | U22: Bitch | V22: 41709 | W22: 0 | X22: 0 | Y22: Not applicable | AA22: Yes | AB22: No | AC22: Yes | AD22: Judging Ch C Bitch Sunday. Camping required Friday-Monday please. _x000D_ Steward Sue Garner
A23: Petersfield & District DTS - SATUDAY 31ST MAY AND SUNDAY 1ST JUNE 2025 | B23: 1500 | C23: Kay Allen | E23: Mrs | F23: Kay | G23: Allen | H23: Maxworthy Barn | I23: Maxworthy | J23: Launceston | K23: Devon | L23: PL15 8LZ | M23: United Kingdom | N23: 1566785587 | O23: kay.allen41@gmail.com | P23: Kay Allen | R23: Torlake Becka | S23: AW00031602 | T23: Border Collie | U23: Bitch | V23: 43422 | W23: 0 | X23: 0 | Y23: Not applicable | AA23: Yes | AB23: No | AC23: Yes | AD23: Judging Ch C Bitch Sunday. Camping required Friday-Monday please. _x000D_ Steward Sue Garner
A24: Petersfield & District DTS - SATUDAY 31ST MAY AND SUNDAY 1ST JUNE 2025 | B24: 1500 | C24: Kay Allen | E24: Mrs | F24: Kay | G24: Allen | H24: Maxworthy Barn | I24: Maxworthy | J24: Launceston | K24: Devon | L24: PL15 8LZ | M24: United Kingdom | N24: 1566785587 | O24: kay.allen41@gmail.com | P24: Kay Allen | R24: Torlake Royal A ex | S24: AU00564401 | T24: Border Collie | U24: Dog | V24: 42744 | W24: 0 | X24: 0 | Y24: Not applicable | AA24: Yes | AB24: No | AC24: Yes | AD24: Judging Ch C Bitch Sunday. Camping required Friday-Monday please. _x000D_ Steward Sue Garner
A25: Petersfield & District DTS - SATUDAY 31ST MAY AND SUNDAY 1ST JUNE 2025 | B25: 1500 | C25: Kay Allen | E25: Mrs | F25: Kay | G25: Allen | H25: Maxworthy Barn | I25: Maxworthy | J25: Launceston | K25: Devon | L25: PL15 8LZ | M25: United Kingdom | N25: 1566785587 | O25: kay.allen41@gmail.com | P25: Kay Allen | R25: Torlake Temple | S25: BA18655305 | T25: Border Collie | U25: Bitch | V25: 44931 | W25: 0 | X25: 0 | Y25: Not applicable | AA25: Yes | AB25: No | AC25: Yes | AD25: Judging Ch C Bitch Sunday. Camping required Friday-Monday please. _x000D_ Steward Sue Garner
A26: Petersfield & District DTS - SATUDAY 31ST MAY AND SUNDAY 1ST JUNE 2025 | B26: 1500 | C26: Kay Allen | E26: Mrs | F26: Kay | G26: Allen | H26: Maxworthy Barn | I26: Maxworthy | J26: Launceston | K26: Devon | L26: PL15 8LZ | M26: United Kingdom | N26: 1566785587 | O26: kay.allen41@gmail.com | P26: Kay Allen | R26: Torlake Becka | S26: AW00031602 | T26: Border Collie | U26: Bitch | V26: 43422 | W26: 0 | X26: 0 | Y26: Not applicable | AA26: Yes | AB26: No | AC26: Yes | AD26: Judging Ch C Bitch Sunday. Camping required Friday-Monday please. _x000D_ Steward Sue Garner
A27: Petersfield & District DTS - SATUDAY 31ST MAY AND SUNDAY 1ST JUNE 2025 | B27: 1500 | C27: Kay Allen | E27: Mrs | F27: Kay | G27: Allen | H27: Maxworthy Barn | I27: Maxworthy | J27: Launceston | K27: Devon | L27: PL15 8LZ | M27: United Kingdom | N27: 1566785587 | O27: kay.allen41@gmail.com | P27: Kay Allen | R27: Torlake Red Nov Ex | S27: AW00031601 | T27: Border Collie | U27: Dog | V27: 43422 | W27: 0 | X27: 0 | Y27: Not applicable | AA27: Yes | AB27: No | AC27: Yes | AD27: Judging Ch C Bitch Sunday. Camping required Friday-Monday please. _x000D_ Steward Sue Garner
A28: Petersfield & District DTS - SATUDAY 31ST MAY AND SUNDAY 1ST JUNE 2025 | B28: 1500 | C28: Kay Allen | E28: Mrs | F28: Kay | G28: Allen | H28: Maxworthy Barn | I28: Maxworthy | J28: Launceston | K28: Devon | L28: PL15 8LZ | M28: United Kingdom | N28: 1566785587 | O28: kay.allen41@gmail.com | P28: Kay Allen | R28: Torlake Royal A ex | S28: AU00564401 | T28: Border Collie | U28: Dog | V28: 42744 | W28: 0 | X28: 0 | Y28: Not applicable | AA28: Yes | AB28: No | AC28: Yes | AD28: Judging Ch C Bitch Sunday. Camping required Friday-Monday please. _x000D_ Steward Sue Garner
A29: Petersfield & District DTS - SATUDAY 31ST MAY AND SUNDAY 1ST JUNE 2025 | B29: 1500 | C29: Kay Allen | E29: Mrs | F29: Kay | G29: Allen | H29: Maxworthy Barn | I29: Maxworthy | J29: Launceston | K29: Devon | L29: PL15 8LZ | M29: United Kingdom | N29: 1566785587 | O29: kay.allen41@gmail.com | P29: Kay Allen | R29: Cories Crystal Lake B Ex AW(B) | S29: AR02059805 | T29: Border Collie | U29: Bitch | V29: 41709 | W29: 0 | X29: 0 | Y29: Not applicable | AA29: Yes | AB29: No | AC29: Yes | AD29: Judging Ch C Bitch Sunday. Camping required Friday-Monday please. _x000D_ Steward Sue Garner
A30: Petersfield & District DTS - SATUDAY 31ST MAY AND SUNDAY 1ST JUNE 2025 | B30: 1500 | C30: Kay Allen | E30: Mrs | F30: Kay | G30: Allen | H30: Maxworthy Barn | I30: Maxworthy | J30: Launceston | K30: Devon | L30: PL15 8LZ | M30: United Kingdom | N30: 1566785587 | O30: kay.allen41@gmail.com | P30: Kay Allen | R30: Torlake Temple | S30: BA18655305 | T30: Border Collie | U30: Bitch | V30: 44931 | W30: 0 | X30: 0 | Y30: Not applicable | AA30: Yes | AB30: No | AC30: Yes | AD30: Judging Ch C Bitch Sunday. Camping required Friday-Monday please. _x000D_ Steward Sue Garner
A31: Petersfield & District DTS - SATUDAY 31ST MAY AND SUNDAY 1ST JUNE 2025 | B31: 701 | C31: Tracy Ansell | D31: 11 | E31: Mrs | F31: Tracy | G31: Ansell | H31: 9 Bates close | J31: HIGHAM FERRES | K31: NORTHANTS | L31: NN10 8HF | M31: United Kingdom | N31: 1933353038 | O31: srallebone9@gmail.com | P31: Tracy Ansell | R31: Buskru Go With the Flo | S31: naf | T31: Crossbreed | U31: Bitch | V31: 44890 | W31: 0 | X31: 4 | Y31: Michelle Richmond | Z31: Camping - Friday night,Camping - Saturday night | AA31: Yes | AB31: No | AC31: No
A32: Petersfield & District DTS - SATUDAY 31ST MAY AND SUNDAY 1ST JUNE 2025 | B32: 701 | C32: Tracy Ansell | D32: 13 | E32: Mrs | F32: Tracy | G32: Ansell | H32: 9 Bates close | J32: HIGHAM FERRES | K32: NORTHANTS | L32: NN10 8HF | M32: United Kingdom | N32: 1933353038 | O32: srallebone9@gmail.com | P32: Tracy Ansell | R32: Tazziemin Strike a Pose for Chalkwell | S32: AZ15444205 | T32: Standard Poodle | U32: Bitch | V32: 44754 | W32: 0 | X32: 6 | Y32: Sue Monk | Z32: Camping - Friday night,Camping - Saturday night | AA32: Yes | AB32: No | AC32: No
A33: Petersfield & District DTS - SATUDAY 31ST MAY AND SUNDAY 1ST JUNE 2025 | B33: 701 | C33: Tracy Ansell | D33: 13 | E33: Mrs | F33: Tracy | G33: Ansell | H33: 9 Bates close | J33: HIGHAM FERRES | K33: NORTHANTS | L33: NN10 8HF | M33: United Kingdom | N33: 1933353038 | O33: srallebone9@gmail.com | P33: Tracy Ansell | R33: Tazziemin Strike a Pose for Chalkwell | S33: AZ15444205 | T33: Standard Poodle | U33: Bitch | V33: 44754 | W33: 0 | X33: 5 | Y33: Kathy Case | Z33: Camping - Friday night,Camping - Saturday night | AA33: Yes | AB33: No | AC33: No
A34: Petersfield & District DTS - SATUDAY 31ST MAY AND SUNDAY 1ST JUNE 2025 | B34: 701 | C34: Tracy Ansell | D34: 12 | E34: Mrs | F34: Tracy | G34: Ansell | H34: 9 Bates close | J34: HIGHAM FERRES | K34: NORTHANTS | L34: NN10 8HF | M34: United Kingdom | N34: 1933353038 | O34: srallebone9@gmail.com | P34: Tracy Ansell | R34: Chalkwell Worth a Shot | S34: AU00900601 | T34: Standard Poodle | U34: Dog | V34: 42657 | W34: 0 | X34: 7 | Z34: Camping - Friday night,Camping - Saturday night | AA34: Yes | AB34: No | AC34: No
A35: Petersfield & District DTS - SATUDAY 31ST MAY AND SUNDAY 1ST JUNE 2025 | B35: 701 | C35: Tracy Ansell | D35: 11 | E35: Mrs | F35: Tracy | G35: Ansell | H35: 9 Bates close | J35: HIGHAM FERRES | K35: NORTHANTS | L35: NN10 8HF | M35: United Kingdom | N35: 1933353038 | O35: srallebone9@gmail.com | P35: Tracy Ansell | R35: Buskru Go With the Flo | S35: naf | T35: Crossbreed | U35: Bitch | V35: 44890 | W35: 0 | X35: 13 | Z35: Camping - Friday night,Camping - Saturday night | AA35: Yes | AB35: No | AC35: No
A36: Petersfield & District DTS - SATUDAY 31ST MAY AND SUNDAY 1ST JUNE 2025 | B36: 701 | C36: Tracy Ansell | D36: 13 | E36: Mrs | F36: Tracy | G36: Ansell | H36: 9 Bates close | J36: HIGHAM FERRES | K36: NORTHANTS | L36: NN10 8HF | M36: United Kingdom | N36: 1933353038 | O36: srallebone9@gmail.com | P36: Tracy Ansell | R36: Tazziemin Strike a Pose for Chalkwell | S36: AZ15444205 | T36: Standard Poodle | U36: Bitch | V36: 44754 | W36: 0 | X36: 15 | Z36: Camping - Friday night,Camping - Saturday night | AA36: Yes | AB36: No | AC36: No
A37: Petersfield & District DTS - SATUDAY 31ST MAY AND SUNDAY 1ST JUNE 2025 | B37: 701 | C37: Tracy Ansell | D37: 13 | E37: Mrs | F37: Tracy | G37: Ansell | H37: 9 Bates close | J37: HIGHAM FERRES | K37: NORTHANTS | L37: NN10 8HF | M37: United Kingdom | N37: 1933353038 | O37: srallebone9@gmail.com | P37: Tracy Ansell | R37: Tazziemin Strike a Pose for Chalkwell | S37: AZ15444205 | T37: Standard Poodle | U37: Bitch | V37: 44754 | W37: 0 | X37: 17 | Z37: Camping - Friday night,Camping - Saturday night | AA37: Yes | AB37: No | AC37: No
A38: Petersfield & District DTS - SATUDAY 31ST MAY AND SUNDAY 1ST JUNE 2025 | B38: 701 | C38: Tracy Ansell | D38: 12 | E38: Mrs | F38: Tracy | G38: Ansell | H38: 9 Bates close | J38: HIGHAM FERRES | K38: NORTHANTS | L38: NN10 8HF | M38: United Kingdom | N38: 1933353038 | O38: srallebone9@gmail.com | P38: Tracy Ansell | R38: Chalkwell Worth a Shot | S38: AU00900601 | T38: Standard Poodle | U38: Dog | V38: 42657 | W38: 0 | X38: 20 | Z38: Camping - Friday night,Camping - Saturday night | AA38: Yes | AB38: No | AC38: No
A39: Petersfield & District DTS - SATUDAY 31ST MAY AND SUNDAY 1ST JUNE 2025 | B39: 701 | C39: Tracy Ansell | E39: Mrs | F39: Tracy | G39: Ansell | H39: 9 Bates close | J39: HIGHAM FERRES | K39: NORTHANTS | L39: NN10 8HF | M39: United Kingdom | N39: 1933353038 | O39: srallebone9@gmail.com | P39: Mrs Tracy Ansell | R39: CH Chalkwell Express Yourself | S39: AP01851801 | T39: Standard Poodle | U39: Dog | V39: 41005 | W39: 0 | X39: 0 | Y39: Not applicable | Z39: Camping - Friday night,Camping - Saturday night | AA39: Yes | AB39: No | AC39: No
A40: Petersfield & District DTS - SATUDAY 31ST MAY AND SUNDAY 1ST JUNE 2025 | B40: 701 | C40: Tracy Ansell | E40: Mrs | F40: Tracy | G40: Ansell | H40: 9 Bates close | J40: HIGHAM FERRES | K40: NORTHANTS | L40: NN10 8HF | M40: United Kingdom | N40: 1933353038 | O40: srallebone9@gmail.com | P40: Mrs Tracy Ansell | R40: Somanic pop the cork for Chalkwell | S40: AW02417801 | T40: standard poodle | U40: Bitch | V40: 43595 | W40: 0 | X40: 0 | Y40: Not applicable | Z40: Camping - Friday night,Camping - Saturday night | AA40: Yes | AB40: No | AC40: No
...

Sheet For import
A1: Show name | B1: Owner Id | C1: Owner title | D1: Owner first name | E1: Owner last name | F1: Owner address 1 | G1: Owner address 2 | H1: Owner town | I1: Owner county | J1: Owner postcode | K1: Owner country | L1: Owner phone | M1: Owner email address | N1: Owner registered name | O1: Vehicle registration | P1: Registered name | Q1: Registered number | R1: Breed | S1: Sex | T1: Date of birth | U1: Merit points | V1: Entered classes | W1: Preferred judge | X1: Extras | Y1: Confirmed acceptance of declaration | Z1: Withdraw all entries if balloted out of Championship C | AA1: Show address in catalogue | AB1: Notes to organiser | AD1: Import
A2: Petersfield & District DTS - SATUDAY 31ST MAY AND SUNDAY 1ST JUNE 2025 | B2: 2670 | C2: Miss | D2: Annie | E2: Abbott | F2: Foster cottage | H2: Wareham | I2: Dorset | J2: BH20 7DL | K2: United Kingdom | L2: 7934997677 | M2: anico16@hotmail.com | N2: Annie Abbott | P2: Mosquito Meep | Q2: F5-13919-2024 | R2: Toy Poodle | S2: Dog | T2: 45309 | U2: 0 | V2: 2 | Y2: Yes | Z2: No | AA2: No
A3: Petersfield & District DTS - SATUDAY 31ST MAY AND SUNDAY 1ST JUNE 2025 | B3: 2670 | C3: Miss | D3: Annie | E3: Abbott | F3: Foster cottage | H3: Wareham | I3: Dorset | J3: BH20 7DL | K3: United Kingdom | L3: 7934997677 | M3: anico16@hotmail.com | N3: Annie Abbott | P3: Ri Coco the Clown | Q3: K159116 | R3: Poodle | S3: Dog | T3: 41476 | U3: 0 | V3: 2 | Y3: Yes | Z3: No | AA3: No | AD3: Y
A4: Petersfield & District DTS - SATUDAY 31ST MAY AND SUNDAY 1ST JUNE 2025 | B4: 2649 | C4: Miss | D4: Susan | E4: Abraham | F4: 5 Camley Close | H4: Southampton | I4: Hampshire | J4: SO19 9GP | K4: United Kingdom | L4: 023 80432000 | M4: sue_abraham56@hotmail.com | N4: Miss S Abraham | P4: KALIAZAR CRUIZE | Q4: AQ01895805 | R4: Border Collie | S4: Dog | T4: 41397 | U4: 0 | V4: 0 | W4: Not applicable | Y4: Yes | Z4: No | AA4: No | AD4: Y
A5: Petersfield & District DTS - SATUDAY 31ST MAY AND SUNDAY 1ST JUNE 2025 | B5: 2649 | C5: Miss | D5: Susan | E5: Abraham | F5: 5 Camley Close | H5: Southampton | I5: Hampshire | J5: SO19 9GP | K5: United Kingdom | L5: 023 80432000 | M5: sue_abraham56@hotmail.com | N5: Miss S Abraham | P5: TIPPIVALE JIVE MAN | Q5: BB27138202 | R5: BORDER COLLIE | S5: Dog | T5: 45630 | U5: 0 | V5: 0 | W5: Not applicable | Y5: Yes | Z5: No | AA5: No | AD5: Y
A6: Petersfield & District DTS - SATUDAY 31ST MAY AND SUNDAY 1ST JUNE 2025 | B6: 2649 | C6: Miss | D6: Susan | E6: Abraham | F6: 5 Camley Close | H6: Southampton | I6: Hampshire | J6: SO19 9GP | K6: United Kingdom | L6: 023 80432000 | M6: sue_abraham56@hotmail.com | N6: Susan Abraham | P6: Kaliazar Eclipse | Q6: AV01178206 | R6: Border Collie | S6: Dog | T6: 43157 | U6: 0 | V6: 4 | W6: Michelle Richmond | Y6: Yes | Z6: No | AA6: No | AD6: Y
A7: Petersfield & District DTS - SATUDAY 31ST MAY AND SUNDAY 1ST JUNE 2025 | B7: 2649 | C7: Miss | D7: Susan | E7: Abraham | F7: 5 Camley Close | H7: Southampton | I7: Hampshire | J7: SO19 9GP | K7: United Kingdom | L7: 023 80432000 | M7: sue_abraham56@hotmail.com | N7: Susan Abraham | P7: Kaliazar Eclipse | Q7: AV01178206 | R7: Border Collie | S7: Dog | T7: 43157 | U7: 0 | V7: 5 | W7: Kathy Case | Y7: Yes | Z7: No | AA7: No | AD7: Y
A8: Petersfield & District DTS - SATUDAY 31ST MAY AND SUNDAY 1ST JUNE 2025 | B8: 2649 | C8: Miss | D8: Susan | E8: Abraham | F8: 5 Camley Close | H8: Southampton | I8: Hampshire | J8: SO19 9GP | K8: United Kingdom | L8: 023 80432000 | M8: sue_abraham56@hotmail.com | N8: Susan Abraham | P8: Kaliazar Eclipse | Q8: AV01178206 | R8: Border Collie | S8: Dog | T8: 43157 | U8: 0 | V8: 12 | Y8: Yes | Z8: No | AA8: No | AD8: Y
A9: Petersfield & District DTS - SATUDAY 31ST MAY AND SUNDAY 1ST JUNE 2025 | B9: 2649 | C9: Miss | D9: Susan | E9: Abraham | F9: 5 Camley Close | H9: Southampton | I9: Hampshire | J9: SO19 9GP | K9: United Kingdom | L9: 023 80432000 | M9: sue_abraham56@hotmail.com | N9: Susan Abraham | P9: Kaliazar Eclipse | Q9: AV01178206 | R9: Border Collie | S9: Dog | T9: 43157 | U9: 0 | V9: 14 | Y9: Yes | Z9: No | AA9: No | AD9: Y
A10: Petersfield & District DTS - SATUDAY 31ST MAY AND SUNDAY 1ST JUNE 2025 | B10: 2999 | C10: Mrs | D10: Sandra | E10: Aburn | F10: 4 Castle Gardens | H10: Dorking | I10: Surrey | J10: RH4 1NY | K10: United Kingdom | L10: 7852469499 | M10: sandra1.bailey@icloud.com | N10: Miss S Bailey | P10: Forevermagic road king | Q10: K0273807 | R10: Working sheepdog | S10: Dog | T10: 45263 | U10: 0 | V10: 0 | W10: Not applicable | Y10: Yes | Z10: No | AA10: No | AD10: Y
A11: Petersfield & District DTS - SATUDAY 31ST MAY AND SUNDAY 1ST JUNE 2025 | B11: 2999 | C11: Mrs | D11: Sandra | E11: Aburn | F11: 4 Castle Gardens | H11: Dorking | I11: Surrey | J11: RH4 1NY | K11: United Kingdom | L11: 7852469499 | M11: sandra1.bailey@icloud.com | N11: Sandra Bailey | P11: Sapphire Inferno Sky | Q11: K164665 | R11: Working Sheepdog | S11: Bitch | T11: 43211 | U11: 0 | V11: 5 | W11: Kathy Case | Y11: Yes | Z11: No | AA11: No | AD11: Y
A12: Petersfield & District DTS - SATUDAY 31ST MAY AND SUNDAY 1ST JUNE 2025 | B12: 2999 | C12: Mrs | D12: Sandra | E12: Aburn | F12: 4 Castle Gardens | H12: Dorking | I12: Surrey | J12: RH4 1NY | K12: United Kingdom | L12: 7852469499 | M12: sandra1.bailey@icloud.com | N12: Sandra Bailey | P12: Sapphire Inferno Sky | Q12: K164665 | R12: Working Sheepdog | S12: Bitch | T12: 43211 | U12: 0 | V12: 6 | W12: Sue Monk | Y12: Yes | Z12: No | AA12: No | AD12: Y
A13: Petersfield & District DTS - SATUDAY 31ST MAY AND SUNDAY 1ST JUNE 2025 | B13: 2999 | C13: Mrs | D13: Sandra | E13: Aburn | F13: 4 Castle Gardens | H13: Dorking | I13: Surrey | J13: RH4 1NY | K13: United Kingdom | L13: 7852469499 | M13: sandra1.bailey@icloud.com | N13: Miss S Bailey | P13: Forevermagic road king | Q13: K0273807 | R13: Working sheepdog | S13: Dog | T13: 45263 | U13: 0 | V13: 0 | W13: Not applicable | Y13: Yes | Z13: No | AA13: No | AD13: Y
A14: Petersfield & District DTS - SATUDAY 31ST MAY AND SUNDAY 1ST JUNE 2025 | B14: 2999 | C14: Mrs | D14: Sandra | E14: Aburn | F14: 4 Castle Gardens | H14: Dorking | I14: Surrey | J14: RH4 1NY | K14: United Kingdom | L14: 7852469499 | M14: sandra1.bailey@icloud.com | N14: Sandra Bailey | P14: Sapphire Inferno Sky | Q14: K164665 | R14: Working Sheepdog | S14: Bitch | T14: 43211 | U14: 0 | V14: 15 | Y14: Yes | Z14: No | AA14: No | AD14: Y
A15: Petersfield & District DTS - SATUDAY 31ST MAY AND SUNDAY 1ST JUNE 2025 | B15: 2999 | C15: Mrs | D15: Sandra | E15: Aburn | F15: 4 Castle Gardens | H15: Dorking | I15: Surrey | J15: RH4 1NY | K15: United Kingdom | L15: 7852469499 | M15: sandra1.bailey@icloud.com | N15: Sandra Bailey | P15: Sapphire Inferno Sky | Q15: K164665 | R15: Working Sheepdog | S15: Bitch | T15: 43211 | U15: 0 | V15: 17 | Y15: Yes | Z15: No | AA15: No | AD15: Y
A16: Petersfield & District DTS - SATUDAY 31ST MAY AND SUNDAY 1ST JUNE 2025 | B16: 2387 | C16: Mrs | D16: Janet | E16: Aldridge | F16: 2 Malabar farm Cottages, Badby Road West | H16: Daventry | I16: Northants | J16: NN114NH | K16: United Kingdom | L16: 447970863728 | M16: johnmalabar@hotmail.com | N16: Janet Aldridge | P16: Malaridge Sappire Sunset | Q16: KO271139 | R16: Working Sheepdog | S16: Bitch | T16: 44971 | U16: 0 | V16: 13 | Y16: Yes | Z16: No | AA16: No | AD16: Y
A17: Petersfield & District DTS - SATUDAY 31ST MAY AND SUNDAY 1ST JUNE 2025 | B17: 2387 | C17: Mrs | D17: Janet | E17: Aldridge | F17: 2 Malabar farm Cottages, Badby Road West | H17: Daventry | I17: Northants | J17: NN114NH | K17: United Kingdom | L17: 447970863728 | M17: johnmalabar@hotmail.com | N17: Janet Aldridge | P17: Tigrys Treacle Tart at Malaridge | Q17: K0261529 | R17: Working Sheepdog | S17: Bitch | T17: 44058 | U17: 0 | V17: 17 | Y17: Yes | Z17: No | AA17: No | AD17: Y
A18: Petersfield & District DTS - SATUDAY 31ST MAY AND SUNDAY 1ST JUNE 2025 | B18: 2387 | C18: Mrs | D18: Janet | E18: Aldridge | F18: 2 Malabar farm Cottages, Badby Road West | H18: Daventry | I18: Northants | J18: NN114NH | K18: United Kingdom | L18: 447970863728 | M18: johnmalabar@hotmail.com | N18: Janet Aldridge | P18: Malaridge Dark Side of Moon | Q18: KO261404 | R18: Working Sheepdog | S18: Dog | T18: 44106 | U18: 0 | V18: 18 | Y18: Yes | Z18: No | AA18: No | AD18: Y
A19: Petersfield & District DTS - SATUDAY 31ST MAY AND SUNDAY 1ST JUNE 2025 | B19: 2387 | C19: Mrs | D19: Janet | E19: Aldridge | F19: 2 Malabar farm Cottages, Badby Road West | H19: Daventry | I19: Northants | J19: NN114NH | K19: United Kingdom | L19: 447970863728 | M19: johnmalabar@hotmail.com | N19: Janet Aldridge | P19: Candlewind Cassanova at Malaridge | Q19: AU01669807 | R19: Border Collie | S19: Dog | T19: 42810 | U19: 0 | V19: 18 | Y19: Yes | Z19: No | AA19: No | AD19: Y
A20: Petersfield & District DTS - SATUDAY 31ST MAY AND SUNDAY 1ST JUNE 2025 | B20: 2387 | C20: Mrs | D20: Janet | E20: Aldridge | F20: 2 Malabar farm Cottages, Badby Road West | H20: Daventry | I20: Northants | J20: NN114NH | K20: United Kingdom | L20: 447970863728 | M20: johnmalabar@hotmail.com | N20: Janet Aldridge | P20: Malaridge Poachers Moon | Q20: K159039 | R20: Working Sheepdog | S20: Bitch | T20: 42996 | U20: 0 | V20: 19 | Y20: Yes | Z20: No | AA20: No | AD20: Y
A21: Petersfield & District DTS - SATUDAY 31ST MAY AND SUNDAY 1ST JUNE 2025 | B21: 1500 | C21: Mrs | D21: Kay | E21: Allen | F21: Maxworthy Barn | G21: Maxworthy | H21: Launceston | I21: Devon | J21: PL15 8LZ | K21: United Kingdom | L21: 1566785587 | M21: kay.allen41@gmail.com | N21: Kay Allen | P21: Torlake Red Nov Ex | Q21: AW00031601 | R21: Border Collie | S21: Dog | T21: 43422 | U21: 0 | V21: 5 | W21: Kathy Case | Y21: Yes | Z21: No | AA21: Yes | AB21: Judging Ch C Bitch Sunday. Camping required Friday-Monday please. _x000D_ Steward Sue Garner | AD21: Y
A22: Petersfield & District DTS - SATUDAY 31ST MAY AND SUNDAY 1ST JUNE 2025 | B22: 1500 | C22: Mrs | D22: Kay | E22: Allen | F22: Maxworthy Barn | G22: Maxworthy | H22: Launceston | I22: Devon | J22: PL15 8LZ | K22: United Kingdom | L22: 1566785587 | M22: kay.allen41@gmail.com | N22: Kay Allen | P22: Cories Crystal Lake B Ex AW(B) | Q22: AR02059805 | R22: Border Collie | S22: Bitch | T22: 41709 | U22: 0 | V22: 0 | W22: Not applicable | Y22: Yes | Z22: No | AA22: Yes | AB22: Judging Ch C Bitch Sunday. Camping required Friday-Monday please. _x000D_ Steward Sue Garner | AD22: Y
A23: Petersfield & District DTS - SATUDAY 31ST MAY AND SUNDAY 1ST JUNE 2025 | B23: 1500 | C23: Mrs | D23: Kay | E23: Allen | F23: Maxworthy Barn | G23: Maxworthy | H23: Launceston | I23: Devon | J23: PL15 8LZ | K23: United Kingdom | L23: 1566785587 | M23: kay.allen41@gmail.com | N23: Kay Allen | P23: Torlake Becka | Q23: AW00031602 | R23: Border Collie | S23: Bitch | T23: 43422 | U23: 0 | V23: 0 | W23: Not applicable | Y23: Yes | Z23: No | AA23: Yes | AB23: Judging Ch C Bitch Sunday. Camping required Friday-Monday please. _x000D_ Steward Sue Garner | AD23: Y
A24: Petersfield & District DTS - SATUDAY 31ST MAY AND SUNDAY 1ST JUNE 2025 | B24: 1500 | C24: Mrs | D24: Kay | E24: Allen | F24: Maxworthy Barn | G24: Maxworthy | H24: Launceston | I24: Devon | J24: PL15 8LZ | K24: United Kingdom | L24: 1566785587 | M24: kay.allen41@gmail.com | N24: Kay Allen | P24: Torlake Royal A ex | Q24: AU00564401 | R24: Border Collie | S24: Dog | T24: 42744 | U24: 0 | V24: 0 | W24: Not applicable | Y24: Yes | Z24: No | AA24: Yes | AB24: Judging Ch C Bitch Sunday. Camping required Friday-Monday please. _x000D_ Steward Sue Garner | AD24: Y
A25: Petersfield & District DTS - SATUDAY 31ST MAY AND SUNDAY 1ST JUNE 2025 | B25: 1500 | C25: Mrs | D25: Kay | E25: Allen | F25: Maxworthy Barn | G25: Maxworthy | H25: Launceston | I25: Devon | J25: PL15 8LZ | K25: United Kingdom | L25: 1566785587 | M25: kay.allen41@gmail.com | N25: Kay Allen | P25: Torlake Temple | Q25: BA18655305 | R25: Border Collie | S25: Bitch | T25: 44931 | U25: 0 | V25: 0 | W25: Not applicable | Y25: Yes | Z25: No | AA25: Yes | AB25: Judging Ch C Bitch Sunday. Camping required Friday-Monday please. _x000D_ Steward Sue Garner | AD25: Y
A26: Petersfield & District DTS - SATUDAY 31ST MAY AND SUNDAY 1ST JUNE 2025 | B26: 1500 | C26: Mrs | D26: Kay | E26: Allen | F26: Maxworthy Barn | G26: Maxworthy | H26: Launceston | I26: Devon | J26: PL15 8LZ | K26: United Kingdom | L26: 1566785587 | M26: kay.allen41@gmail.com | N26: Kay Allen | P26: Torlake Becka | Q26: AW00031602 | R26: Border Collie | S26: Bitch | T26: 43422 | U26: 0 | V26: 0 | W26: Not applicable | Y26: Yes | Z26: No | AA26: Yes | AB26: Judging Ch C Bitch Sunday. Camping required Friday-Monday please. _x000D_ Steward Sue Garner | AD26: Y
A27: Petersfield & District DTS - SATUDAY 31ST MAY AND SUNDAY 1ST JUNE 2025 | B27: 1500 | C27: Mrs | D27: Kay | E27: Allen | F27: Maxworthy Barn | G27: Maxworthy | H27: Launceston | I27: Devon | J27: PL15 8LZ | K27: United Kingdom | L27: 1566785587 | M27: kay.allen41@gmail.com | N27: Kay Allen | P27: Torlake Red Nov Ex | Q27: AW00031601 | R27: Border Collie | S27: Dog | T27: 43422 | U27: 0 | V27: 0 | W27: Not applicable | Y27: Yes | Z27: No | AA27: Yes | AB27: Judging Ch C Bitch Sunday. Camping required Friday-Monday please. _x000D_ Steward Sue Garner | AD27: Y
A28: Petersfield & District DTS - SATUDAY 31ST MAY AND SUNDAY 1ST JUNE 2025 | B28: 1500 | C28: Mrs | D28: Kay | E28: Allen | F28: Maxworthy Barn | G28: Maxworthy | H28: Launceston | I28: Devon | J28: PL15 8LZ | K28: United Kingdom | L28: 1566785587 | M28: kay.allen41@gmail.com | N28: Kay Allen | P28: Torlake Royal A ex | Q28: AU00564401 | R28: Border Collie | S28: Dog | T28: 42744 | U28: 0 | V28: 0 | W28: Not applicable | Y28: Yes | Z28: No | AA28: Yes | AB28: Judging Ch C Bitch Sunday. Camping required Friday-Monday please. _x000D_ Steward Sue Garner | AD28: Y
A29: Petersfield & District DTS - SATUDAY 31ST MAY AND SUNDAY 1ST JUNE 2025 | B29: 1500 | C29: Mrs | D29: Kay | E29: Allen | F29: Maxworthy Barn | G29: Maxworthy | H29: Launceston | I29: Devon | J29: PL15 8LZ | K29: United Kingdom | L29: 1566785587 | M29: kay.allen41@gmail.com | N29: Kay Allen | P29: Cories Crystal Lake B Ex AW(B) | Q29: AR02059805 | R29: Border Collie | S29: Bitch | T29: 41709 | U29: 0 | V29: 0 | W29: Not applicable | Y29: Yes | Z29: No | AA29: Yes | AB29: Judging Ch C Bitch Sunday. Camping required Friday-Monday please. _x000D_ Steward Sue Garner | AD29: Y
A30: Petersfield & District DTS - SATUDAY 31ST MAY AND SUNDAY 1ST JUNE 2025 | B30: 1500 | C30: Mrs | D30: Kay | E30: Allen | F30: Maxworthy Barn | G30: Maxworthy | H30: Launceston | I30: Devon | J30: PL15 8LZ | K30: United Kingdom | L30: 1566785587 | M30: kay.allen41@gmail.com | N30: Kay Allen | P30: Torlake Temple | Q30: BA18655305 | R30: Border Collie | S30: Bitch | T30: 44931 | U30: 0 | V30: 0 | W30: Not applicable | Y30: Yes | Z30: No | AA30: Yes | AB30: Judging Ch C Bitch Sunday. Camping required Friday-Monday please. _x000D_ Steward Sue Garner | AD30: Y
A31: Petersfield & District DTS - SATUDAY 31ST MAY AND SUNDAY 1ST JUNE 2025 | B31: 701 | C31: Mrs | D31: Tracy | E31: Ansell | F31: 9 Bates close | H31: HIGHAM FERRES | I31: NORTHANTS | J31: NN10 8HF | K31: United Kingdom | L31: 1933353038 | M31: srallebone9@gmail.com | N31: Tracy Ansell | P31: Buskru Go With the Flo | Q31: naf | R31: Crossbreed | S31: Bitch | T31: 44890 | U31: 0 | V31: 4 | W31: Michelle Richmond | X31: Camping - Friday night,Camping - Saturday night | Y31: Yes | Z31: No | AA31: No | AD31: Y
A32: Petersfield & District DTS - SATUDAY 31ST MAY AND SUNDAY 1ST JUNE 2025 | B32: 701 | C32: Mrs | D32: Tracy | E32: Ansell | F32: 9 Bates close | H32: HIGHAM FERRES | I32: NORTHANTS | J32: NN10 8HF | K32: United Kingdom | L32: 1933353038 | M32: srallebone9@gmail.com | N32: Tracy Ansell | P32: Tazziemin Strike a Pose for Chalkwell | Q32: AZ15444205 | R32: Standard Poodle | S32: Bitch | T32: 44754 | U32: 0 | V32: 6 | W32: Sue Monk | X32: Camping - Friday night,Camping - Saturday night | Y32: Yes | Z32: No | AA32: No | AD32: Y
A33: Petersfield & District DTS - SATUDAY 31ST MAY AND SUNDAY 1ST JUNE 2025 | B33: 701 | C33: Mrs | D33: Tracy | E33: Ansell | F33: 9 Bates close | H33: HIGHAM FERRES | I33: NORTHANTS | J33: NN10 8HF | K33: United Kingdom | L33: 1933353038 | M33: srallebone9@gmail.com | N33: Tracy Ansell | P33: Tazziemin Strike a Pose for Chalkwell | Q33: AZ15444205 | R33: Standard Poodle | S33: Bitch | T33: 44754 | U33: 0 | V33: 5 | W33: Kathy Case | X33: Camping - Friday night,Camping - Saturday night | Y33: Yes | Z33: No | AA33: No | AD33: Y
A34: Petersfield & District DTS - SATUDAY 31ST MAY AND SUNDAY 1ST JUNE 2025 | B34: 701 | C34: Mrs | D34: Tracy | E34: Ansell | F34: 9 Bates close | H34: HIGHAM FERRES | I34: NORTHANTS | J34: NN10 8HF | K34: United Kingdom | L34: 1933353038 | M34: srallebone9@gmail.com | N34: Tracy Ansell | P34: Chalkwell Worth a Shot | Q34: AU00900601 | R34: Standard Poodle | S34: Dog | T34: 42657 | U34: 0 | V34: 7 | X34: Camping - Friday night,Camping - Saturday night | Y34: Yes | Z34: No | AA34: No | AD34: Y
A35: Petersfield & District DTS - SATUDAY 31ST MAY AND SUNDAY 1ST JUNE 2025 | B35: 701 | C35: Mrs | D35: Tracy | E35: Ansell | F35: 9 Bates close | H35: HIGHAM FERRES | I35: NORTHANTS | J35: NN10 8HF | K35: United Kingdom | L35: 1933353038 | M35: srallebone9@gmail.com | N35: Tracy Ansell | P35: Buskru Go With the Flo | Q35: naf | R35: Crossbreed | S35: Bitch | T35: 44890 | U35: 0 | V35: 13 | X35: Camping - Friday night,Camping - Saturday night | Y35: Yes | Z35: No | AA35: No | AD35: Y
A36: Petersfield & District DTS - SATUDAY 31ST MAY AND SUNDAY 1ST JUNE 2025 | B36: 701 | C36: Mrs | D36: Tracy | E36: Ansell | F36: 9 Bates close | H36: HIGHAM FERRES | I36: NORTHANTS | J36: NN10 8HF | K36: United Kingdom | L36: 1933353038 | M36: srallebone9@gmail.com | N36: Tracy Ansell | P36: Tazziemin Strike a Pose for Chalkwell | Q36: AZ15444205 | R36: Standard Poodle | S36: Bitch | T36: 44754 | U36: 0 | V36: 15 | X36: Camping - Friday night,Camping - Saturday night | Y36: Yes | Z36: No | AA36: No | AD36: Y
